Workbook

Sheet Instructions
B2: DEBT PAYOFF CALCULATOR
B3: Your step-by-step guide to becoming debt-free
B5: Welcome!
B6: Congratulations on taking the first step toward financial freedom! This calculator will help you create a clear, actionable plan to pay off all of your debts. Simply enter your debts on the "Debt Input" sheet, set your extra monthly payment, and the calculator does the rest -- generating personalized Snowball and Avalanche payoff plans so you can compare strategies and choose the best path for you.
B8: How to Use This Calculator
B9: Step 1: Go to the "Debt Input" sheet and enter each debt -- name, balance, APR, and minimum payment.
B10: Step 2: On the "Dashboard" sheet, enter your Extra Monthly Payment (the highlighted yellow cell). Even $50/month makes a huge difference!
B11: Step 3: Review the "Snowball Plan" sheet to see your payoff schedule when tackling the smallest balance first.
B12: Step 4: Review the "Avalanche Plan" sheet to see your payoff schedule when tackling the highest interest rate first.
B13: Step 5: Check the "Comparison" sheet to see which method saves you the most money and time.
B14: Step 6: Print your chosen plan and stick it on the fridge!
B16: Snowball Method vs. Avalanche Method
... B35: NOTE: Yellow-highlighted cells are for your input. All other cells contain formulas -- please do not edit them.

Sheet Dashboard
B1: DEBT PAYOFF DASHBOARD
B2: Your complete debt snapshot at a glance
B4: OVERVIEW
B5: Total Debt | C5: ='Debt Input'!C25
B6: Total Minimum Payments | C6: ='Debt Input'!E25
B7: Number of Debts | C7: =COUNTA('Debt Input'!B5:B24)
B8: Weighted Avg Interest Rate | C8: ='Debt Input'!D25
B10: YOUR EXTRA MONTHLY PAYMENT
B11: Extra Payment Per Month --> | C11: 200 | D11: <-- Enter your extra monthly payment here
B13: PAYOFF COMPARISON
B14: Metric | C14: Snowball | E14: Avalanche
B15: Total Months to Payoff | C15: ='Comparison'!C5 | E15: ='Comparison'!D5
B16: Total Interest Paid | C16: ='Comparison'!C6 | E16: ='Comparison'!D6
B17: Total Amount Paid | C17: ='Comparison'!C7 | E17: ='Comparison'!D7
B18: Interest Saved (Best Method) | C18: ='Comparison'!C9
B19: Recommended Method | C19: ='Comparison'!C10
B21: MOTIVATION STATION
B22: Debt-Free Countdown (Best Method) | C22: =IF('Comparison'!C11=0,"Enter your debts to begin!",'Comparison'!C11&" months to freedom!")
B23: Monthly Payment (Min + Extra) | C23: ='Debt Input'!E25+Dashboard!C11
B25: "The secret of getting ahead is getting started." -- Mark Twain
B26: "A journey of a thousand miles begins with a single step." -- Lao Tzu
B27: "Financial freedom is available to those who learn about it and work for it." -- Robert Kiyosaki

Sheet Debt Input
B1: DEBT PAYOFF CALCULATOR
B2: Enter your debts below. Yellow cells are for your input.
B4: Debt Name | C4: Current Balance | D4: Interest Rate (APR %) | E4: Minimum Payment | F4: Type
B5: Credit Card A | C5: 4500 | D5: 0.2199 | E5: 90 | F5: Credit Card
B6: Student Loan | C6: 12000 | D6: 0.055 | E6: 150 | F6: Student Loan
B7: Car Loan | C7: 8500 | D7: 0.069 | E7: 250 | F7: Car Loan
B8: Personal Loan | C8: 3000 | D8: 0.1099 | E8: 75 | F8: Personal Loan
B9: Medical Bill | C9: 1500 | D9: 0 | E9: 50 | F9: Medical
B25: TOTALS | C25: =SUMIF(C5:C24,">0") | D25: =IF(SUMIF(C5:C24,">0")=0,0,SUMPRODUCT(C5:C24,D5:D24)/SUMIF(C5:C24,">0")) | E25: =SUMIF(E5:E24,">0")

Sheet Snowball Plan
B1: SNOWBALL PLAN (Smallest Balance First)
B2: Month-by-month payment schedule. Green cells = debt paid off!
B4: # | C4: Debt Name | D4: Balance | E4: APR % | F4: Min Payment
B5: 1 | C5: =IFERROR(INDEX('Debt Input'!B$5:B$24,MATCH(1,AI$5:AI$24,0)),"") | D5: =IFERROR(INDEX('Debt Input'!C$5:C$24,MATCH(1,AI$5:AI$24,0)),0) | E5: =IFERROR(INDEX('Debt Input'!D$5:D$24,MATCH(1,AI$5:AI$24,0)),0) | F5: =IFERROR(INDEX('Debt Input'!E$5:E$24,MATCH(1,AI$5:AI$24,0)),0) | AD5: 1 | AE5: ='Debt Input'!C5 | AF5: ='Debt Input'!D5 | AG5: =IF(AE5>0,1,0) | AH5: =IF(AG5=0,9999999999,AE5+AD5*0.00001) | AI5: =RANK(AH5,AH$5:AH$24,1)
B6: 2 | C6: =IFERROR(INDEX('Debt Input'!B$5:B$24,MATCH(2,AI$5:AI$24,0)),"") | D6: =IFERROR(INDEX('Debt Input'!C$5:C$24,MATCH(2,AI$5:AI$24,0)),0) | E6: =IFERROR(INDEX('Debt Input'!D$5:D$24,MATCH(2,AI$5:AI$24,0)),0) | F6: =IFERROR(INDEX('Debt Input'!E$5:E$24,MATCH(2,AI$5:AI$24,0)),0) | AD6: 2 | AE6: ='Debt Input'!C6 | AF6: ='Debt Input'!D6 | AG6: =IF(AE6>0,1,0) | AH6: =IF(AG6=0,9999999999,AE6+AD6*0.00001) | AI6: =RANK(AH6,AH$5:AH$24,1)
B7: 3 | C7: =IFERROR(INDEX('Debt Input'!B$5:B$24,MATCH(3,AI$5:AI$24,0)),"") | D7: =IFERROR(INDEX('Debt Input'!C$5:C$24,MATCH(3,AI$5:AI$24,0)),0) | E7: =IFERROR(INDEX('Debt Input'!D$5:D$24,MATCH(3,AI$5:AI$24,0)),0) | F7: =IFERROR(INDEX('Debt Input'!E$5:E$24,MATCH(3,AI$5:AI$24,0)),0) | AD7: 3 | AE7: ='Debt Input'!C7 | AF7: ='Debt Input'!D7 | AG7: =IF(AE7>0,1,0) | AH7: =IF(AG7=0,9999999999,AE7+AD7*0.00001) | AI7: =RANK(AH7,AH$5:AH$24,1)
B8: 4 | C8: =IFERROR(INDEX('Debt Input'!B$5:B$24,MATCH(4,AI$5:AI$24,0)),"") | D8: =IFERROR(INDEX('Debt Input'!C$5:C$24,MATCH(4,AI$5:AI$24,0)),0) | E8: =IFERROR(INDEX('Debt Input'!D$5:D$24,MATCH(4,AI$5:AI$24,0)),0) | F8: =IFERROR(INDEX('Debt Input'!E$5:E$24,MATCH(4,AI$5:AI$24,0)),0) | AD8: 4 | AE8: ='Debt Input'!C8 | AF8: ='Debt Input'!D8 | AG8: =IF(AE8>0,1,0) | AH8: =IF(AG8=0,9999999999,AE8+AD8*0.00001) | AI8: =RANK(AH8,AH$5:AH$24,1)
B9: 5 | C9: =IFERROR(INDEX('Debt Input'!B$5:B$24,MATCH(5,AI$5:AI$24,0)),"") | D9: =IFERROR(INDEX('Debt Input'!C$5:C$24,MATCH(5,AI$5:AI$24,0)),0) | E9: =IFERROR(INDEX('Debt Input'!D$5:D$24,MATCH(5,AI$5:AI$24,0)),0) | F9: =IFERROR(INDEX('Debt Input'!E$5:E$24,MATCH(5,AI$5:AI$24,0)),0) | AD9: 5 | AE9: ='Debt Input'!C9 | AF9: ='Debt Input'!D9 | AG9: =IF(AE9>0,1,0) | AH9: =IF(AG9=0,9999999999,AE9+AD9*0.00001) | AI9: =RANK(AH9,AH$5:AH$24,1)
B10: 6 | C10: =IFERROR(INDEX('Debt Input'!B$5:B$24,MATCH(6,AI$5:AI$24,0)),"") | D10: =IFERROR(INDEX('Debt Input'!C$5:C$24,MATCH(6,AI$5:AI$24,0)),0) | E10: =IFERROR(INDEX('Debt Input'!D$5:D$24,MATCH(6,AI$5:AI$24,0)),0) | F10: =IFERROR(INDEX('Debt Input'!E$5:E$24,MATCH(6,AI$5:AI$24,0)),0) | AD10: 6 | AE10: ='Debt Input'!C10 | AF10: ='Debt Input'!D10 | AG10: =IF(AE10>0,1,0) | AH10: =IF(AG10=0,9999999999,AE10+AD10*0.00001) | AI10: =RANK(AH10,AH$5:AH$24,1)
B11: 7 | C11: =IFERROR(INDEX('Debt Input'!B$5:B$24,MATCH(7,AI$5:AI$24,0)),"") | D11: =IFERROR(INDEX('Debt Input'!C$5:C$24,MATCH(7,AI$5:AI$24,0)),0) | E11: =IFERROR(INDEX('Debt Input'!D$5:D$24,MATCH(7,AI$5:AI$24,0)),0) | F11: =IFERROR(INDEX('Debt Input'!E$5:E$24,MATCH(7,AI$5:AI$24,0)),0) | AD11: 7 | AE11: ='Debt Input'!C11 | AF11: ='Debt Input'!D11 | AG11: =IF(AE11>0,1,0) | AH11: =IF(AG11=0,9999999999,AE11+AD11*0.00001) | AI11: =RANK(AH11,AH$5:AH$24,1)
B12: 8 | C12: =IFERROR(INDEX('Debt Input'!B$5:B$24,MATCH(8,AI$5:AI$24,0)),"") | D12: =IFERROR(INDEX('Debt Input'!C$5:C$24,MATCH(8,AI$5:AI$24,0)),0) | E12: =IFERROR(INDEX('Debt Input'!D$5:D$24,MATCH(8,AI$5:AI$24,0)),0) | F12: =IFERROR(INDEX('Debt Input'!E$5:E$24,MATCH(8,AI$5:AI$24,0)),0) | AD12: 8 | AE12: ='Debt Input'!C12 | AF12: ='Debt Input'!D12 | AG12: =IF(AE12>0,1,0) | AH12: =IF(AG12=0,9999999999,AE12+AD12*0.00001) | AI12: =RANK(AH12,AH$5:AH$24,1)
B13: 9 | C13: =IFERROR(INDEX('Debt Input'!B$5:B$24,MATCH(9,AI$5:AI$24,0)),"") | D13: =IFERROR(INDEX('Debt Input'!C$5:C$24,MATCH(9,AI$5:AI$24,0)),0) | E13: =IFERROR(INDEX('Debt Input'!D$5:D$24,MATCH(9,AI$5:AI$24,0)),0) | F13: =IFERROR(INDEX('Debt Input'!E$5:E$24,MATCH(9,AI$5:AI$24,0)),0) | AD13: 9 | AE13: ='Debt Input'!C13 | AF13: ='Debt Input'!D13 | AG13: =IF(AE13>0,1,0) | AH13: =IF(AG13=0,9999999999,AE13+AD13*0.00001) | AI13: =RANK(AH13,AH$5:AH$24,1)
B14: 10 | C14: =IFERROR(INDEX('Debt Input'!B$5:B$24,MATCH(10,AI$5:AI$24,0)),"") | D14: =IFERROR(INDEX('Debt Input'!C$5:C$24,MATCH(10,AI$5:AI$24,0)),0) | E14: =IFERROR(INDEX('Debt Input'!D$5:D$24,MATCH(10,AI$5:AI$24,0)),0) | F14: =IFERROR(INDEX('Debt Input'!E$5:E$24,MATCH(10,AI$5:AI$24,0)),0) | AD14: 10 | AE14: ='Debt Input'!C14 | AF14: ='Debt Input'!D14 | AG14: =IF(AE14>0,1,0) | AH14: =IF(AG14=0,9999999999,AE14+AD14*0.00001) | AI14: =RANK(AH14,AH$5:AH$24,1)
B15: 11 | C15: =IFERROR(INDEX('Debt Input'!B$5:B$24,MATCH(11,AI$5:AI$24,0)),"") | D15: =IFERROR(INDEX('Debt Input'!C$5:C$24,MATCH(11,AI$5:AI$24,0)),0) | E15: =IFERROR(INDEX('Debt Input'!D$5:D$24,MATCH(11,AI$5:AI$24,0)),0) | F15: =IFERROR(INDEX('Debt Input'!E$5:E$24,MATCH(11,AI$5:AI$24,0)),0) | AD15: 11 | AE15: ='Debt Input'!C15 | AF15: ='Debt Input'!D15 | AG15: =IF(AE15>0,1,0) | AH15: =IF(AG15=0,9999999999,AE15+AD15*0.00001) | AI15: =RANK(AH15,AH$5:AH$24,1)
B16: 12 | C16: =IFERROR(INDEX('Debt Input'!B$5:B$24,MATCH(12,AI$5:AI$24,0)),"") | D16: =IFERROR(INDEX('Debt Input'!C$5:C$24,MATCH(12,AI$5:AI$24,0)),0) | E16: =IFERROR(INDEX('Debt Input'!D$5:D$24,MATCH(12,AI$5:AI$24,0)),0) | F16: =IFERROR(INDEX('Debt Input'!E$5:E$24,MATCH(12,AI$5:AI$24,0)),0) | AD16: 12 | AE16: ='Debt Input'!C16 | AF16: ='Debt Input'!D16 | AG16: =IF(AE16>0,1,0) | AH16: =IF(AG16=0,9999999999,AE16+AD16*0.00001) | AI16: =RANK(AH16,AH$5:AH$24,1)
B17: 13 | C17: =IFERROR(INDEX('Debt Input'!B$5:B$24,MATCH(13,AI$5:AI$24,0)),"") | D17: =IFERROR(INDEX('Debt Input'!C$5:C$24,MATCH(13,AI$5:AI$24,0)),0) | E17: =IFERROR(INDEX('Debt Input'!D$5:D$24,MATCH(13,AI$5:AI$24,0)),0) | F17: =IFERROR(INDEX('Debt Input'!E$5:E$24,MATCH(13,AI$5:AI$24,0)),0) | AD17: 13 | AE17: ='Debt Input'!C17 | AF17: ='Debt Input'!D17 | AG17: =IF(AE17>0,1,0) | AH17: =IF(AG17=0,9999999999,AE17+AD17*0.00001) | AI17: =RANK(AH17,AH$5:AH$24,1)
B18: 14 | C18: =IFERROR(INDEX('Debt Input'!B$5:B$24,MATCH(14,AI$5:AI$24,0)),"") | D18: =IFERROR(INDEX('Debt Input'!C$5:C$24,MATCH(14,AI$5:AI$24,0)),0) | E18: =IFERROR(INDEX('Debt Input'!D$5:D$24,MATCH(14,AI$5:AI$24,0)),0) | F18: =IFERROR(INDEX('Debt Input'!E$5:E$24,MATCH(14,AI$5:AI$24,0)),0) | AD18: 14 | AE18: ='Debt Input'!C18 | AF18: ='Debt Input'!D18 | AG18: =IF(AE18>0,1,0) | AH18: =IF(AG18=0,9999999999,AE18+AD18*0.00001) | AI18: =RANK(AH18,AH$5:AH$24,1)
B19: 15 | C19: =IFERROR(INDEX('Debt Input'!B$5:B$24,MATCH(15,AI$5:AI$24,0)),"") | D19: =IFERROR(INDEX('Debt Input'!C$5:C$24,MATCH(15,AI$5:AI$24,0)),0) | E19: =IFERROR(INDEX('Debt Input'!D$5:D$24,MATCH(15,AI$5:AI$24,0)),0) | F19: =IFERROR(INDEX('Debt Input'!E$5:E$24,MATCH(15,AI$5:AI$24,0)),0) | AD19: 15 | AE19: ='Debt Input'!C19 | AF19: ='Debt Input'!D19 | AG19: =IF(AE19>0,1,0) | AH19: =IF(AG19=0,9999999999,AE19+AD19*0.00001) | AI19: =RANK(AH19,AH$5:AH$24,1)
B20: 16 | C20: =IFERROR(INDEX('Debt Input'!B$5:B$24,MATCH(16,AI$5:AI$24,0)),"") | D20: =IFERROR(INDEX('Debt Input'!C$5:C$24,MATCH(16,AI$5:AI$24,0)),0) | E20: =IFERROR(INDEX('Debt Input'!D$5:D$24,MATCH(16,AI$5:AI$24,0)),0) | F20: =IFERROR(INDEX('Debt Input'!E$5:E$24,MATCH(16,AI$5:AI$24,0)),0) | AD20: 16 | AE20: ='Debt Input'!C20 | AF20: ='Debt Input'!D20 | AG20: =IF(AE20>0,1,0) | AH20: =IF(AG20=0,9999999999,AE20+AD20*0.00001) | AI20: =RANK(AH20,AH$5:AH$24,1)
B21: 17 | C21: =IFERROR(INDEX('Debt Input'!B$5:B$24,MATCH(17,AI$5:AI$24,0)),"") | D21: =IFERROR(INDEX('Debt Input'!C$5:C$24,MATCH(17,AI$5:AI$24,0)),0) | E21: =IFERROR(INDEX('Debt Input'!D$5:D$24,MATCH(17,AI$5:AI$24,0)),0) | F21: =IFERROR(INDEX('Debt Input'!E$5:E$24,MATCH(17,AI$5:AI$24,0)),0) | AD21: 17 | AE21: ='Debt Input'!C21 | AF21: ='Debt Input'!D21 | AG21: =IF(AE21>0,1,0) | AH21: =IF(AG21=0,9999999999,AE21+AD21*0.00001) | AI21: =RANK(AH21,AH$5:AH$24,1)
B22: 18 | C22: =IFERROR(INDEX('Debt Input'!B$5:B$24,MATCH(18,AI$5:AI$24,0)),"") | D22: =IFERROR(INDEX('Debt Input'!C$5:C$24,MATCH(18,AI$5:AI$24,0)),0) | E22: =IFERROR(INDEX('Debt Input'!D$5:D$24,MATCH(18,AI$5:AI$24,0)),0) | F22: =IFERROR(INDEX('Debt Input'!E$5:E$24,MATCH(18,AI$5:AI$24,0)),0) | AD22: 18 | AE22: ='Debt Input'!C22 | AF22: ='Debt Input'!D22 | AG22: =IF(AE22>0,1,0) | AH22: =IF(AG22=0,9999999999,AE22+AD22*0.00001) | AI22: =RANK(AH22,AH$5:AH$24,1)
B23: 19 | C23: =IFERROR(INDEX('Debt Input'!B$5:B$24,MATCH(19,AI$5:AI$24,0)),"") | D23: =IFERROR(INDEX('Debt Input'!C$5:C$24,MATCH(19,AI$5:AI$24,0)),0) | E23: =IFERROR(INDEX('Debt Input'!D$5:D$24,MATCH(19,AI$5:AI$24,0)),0) | F23: =IFERROR(INDEX('Debt Input'!E$5:E$24,MATCH(19,AI$5:AI$24,0)),0) | AD23: 19 | AE23: ='Debt Input'!C23 | AF23: ='Debt Input'!D23 | AG23: =IF(AE23>0,1,0) | AH23: =IF(AG23=0,9999999999,AE23+AD23*0.00001) | AI23: =RANK(AH23,AH$5:AH$24,1)
B24: 20 | C24: =IFERROR(INDEX('Debt Input'!B$5:B$24,MATCH(20,AI$5:AI$24,0)),"") | D24: =IFERROR(INDEX('Debt Input'!C$5:C$24,MATCH(20,AI$5:AI$24,0)),0) | E24: =IFERROR(INDEX('Debt Input'!D$5:D$24,MATCH(20,AI$5:AI$24,0)),0) | F24: =IFERROR(INDEX('Debt Input'!E$5:E$24,MATCH(20,AI$5:AI$24,0)),0) | AD24: 20 | AE24: ='Debt Input'!C24 | AF24: ='Debt Input'!D24 | AG24: =IF(AE24>0,1,0) | AH24: =IF(AG24=0,9999999999,AE24+AD24*0.00001) | AI24: =RANK(AH24,AH$5:AH$24,1)
B26: Month | C26: =IF(C5="","",C5) | D26: =IF(C6="","",C6) | E26: =IF(C7="","",C7) | F26: =IF(C8="","",C8) | G26: =IF(C9="","",C9) | H26: =IF(C10="","",C10) | I26: =IF(C11="","",C11) | J26: =IF(C12="","",C12) | K26: =IF(C13="","",C13) | L26: =IF(C14="","",C14) | M26: =IF(C15="","",C15) | N26: =IF(C16="","",C16) | O26: =IF(C17="","",C17) | P26: =IF(C18="","",C18) | Q26: =IF(C19="","",C19) | R26: =IF(C20="","",C20) | S26: =IF(C21="","",C21) | T26: =IF(C22="","",C22) | U26: =IF(C23="","",C23) | V26: =IF(C24="","",C24) | W26: Total Payment | X26: Interest Paid | Y26: Remaining Balance
B27: 1 | C27: =IF($D$5<=0,0,MAX(0,$D$5+AN27-AO27)) | D27: =IF($D$6<=0,0,MAX(0,$D$6+AQ27-AR27)) | E27: =IF($D$7<=0,0,MAX(0,$D$7+AT27-AU27)) | F27: =IF($D$8<=0,0,MAX(0,$D$8+AW27-AX27)) | G27: =IF($D$9<=0,0,MAX(0,$D$9+AZ27-BA27)) | H27: =IF($D$10<=0,0,MAX(0,$D$10+BC27-BD27)) | I27: =IF($D$11<=0,0,MAX(0,$D$11+BF27-BG27)) | J27: =IF($D$12<=0,0,MAX(0,$D$12+BI27-BJ27)) | K27: =IF($D$13<=0,0,MAX(0,$D$13+BL27-BM27)) | L27: =IF($D$14<=0,0,MAX(0,$D$14+BO27-BP27)) | M27: =IF($D$15<=0,0,MAX(0,$D$15+BR27-BS27)) | N27: =IF($D$16<=0,0,MAX(0,$D$16+BU27-BV27)) | O27: =IF($D$17<=0,0,MAX(0,$D$17+BX27-BY27)) | P27: =IF($D$18<=0,0,MAX(0,$D$18+CA27-CB27)) | Q27: =IF($D$19<=0,0,MAX(0,$D$19+CD27-CE27)) | R27: =IF($D$20<=0,0,MAX(0,$D$20+CG27-CH27)) | S27: =IF($D$21<=0,0,MAX(0,$D$21+CJ27-CK27)) | T27: =IF($D$22<=0,0,MAX(0,$D$22+CM27-CN27)) | U27: =IF($D$23<=0,0,MAX(0,$D$23+CP27-CQ27)) | V27: =IF($D$24<=0,0,MAX(0,$D$24+CS27-CT27)) | W27: =AO27+AR27+AU27+AX27+BA27+BD27+BG27+BJ27+BM27+BP27+BS27+BV27+BY27+CB27+CE27+CH27+CK27+CN27+CQ27+CT27 | X27: =AN27+AQ27+AT27+AW27+AZ27+BC27+BF27+BI27+BL27+BO27+BR27+BU27+BX27+CA27+CD27+CG27+CJ27+CM27+CP27+CS27 | Y27: =C27+D27+E27+F27+G27+H27+I27+J27+K27+L27+M27+N27+O27+P27+Q27+R27+S27+T27+U27+V27 | AN27: =IF($D$5<=0,0,$D$5*$E$5/12) | AO27: =IF($D$5<=0,0,MIN($D$5+AN27,$F$5+Dashboard!$C$11)) | AP27: =IF($D$5<=0,Dashboard!$C$11,MAX(0,$F$5+Dashboard!$C$11-$D$5-AN27)) | AQ27: =IF($D$6<=0,0,$D$6*$E$6/12) | AR27: =IF($D$6<=0,0,MIN($D$6+AQ27,$F$6+AP27)) | AS27: =IF($D$6<=0,AP27,MAX(0,$F$6+AP27-$D$6-AQ27)) | AT27: =IF($D$7<=0,0,$D$7*$E$7/12) | AU27: =IF($D$7<=0,0,MIN($D$7+AT27,$F$7+AS27)) | AV27: =IF($D$7<=0,AS27,MAX(0,$F$7+AS27-$D$7-AT27)) | AW27: =IF($D$8<=0,0,$D$8*$E$8/12) | AX27: =IF($D$8<=0,0,MIN($D$8+AW27,$F$8+AV27)) | AY27: =IF($D$8<=0,AV27,MAX(0,$F$8+AV27-$D$8-AW27)) | AZ27: =IF($D$9<=0,0,$D$9*$E$9/12) | BA27: =IF($D$9<=0,0,MIN($D$9+AZ27,$F$9+AY27)) | BB27: =IF($D$9<=0,AY27,MAX(0,$F$9+AY27-$D$9-AZ27)) | BC27: =IF($D$10<=0,0,$D$10*$E$10/12) | BD27: =IF($D$10<=0,0,MIN($D$10+BC27,$F$10+BB27)) | BE27: =IF($D$10<=0,BB27,MAX(0,$F$10+BB27-$D$10-BC27)) | BF27: =IF($D$11<=0,0,$D$11*$E$11/12) | BG27: =IF($D$11<=0,0,MIN($D$11+BF27,$F$11+BE27)) | BH27: =IF($D$11<=0,BE27,MAX(0,$F$11+BE27-$D$11-BF27)) | BI27: =IF($D$12<=0,0,$D$12*$E$12/12) | BJ27: =IF($D$12<=0,0,MIN($D$12+BI27,$F$12+BH27)) | BK27: =IF($D$12<=0,BH27,MAX(0,$F$12+BH27-$D$12-BI27)) | BL27: =IF($D$13<=0,0,$D$13*$E$13/12) | BM27: =IF($D$13<=0,0,MIN($D$13+BL27,$F$13+BK27)) | BN27: =IF($D$13<=0,BK27,MAX(0,$F$13+BK27-$D$13-BL27)) | BO27: =IF($D$14<=0,0,$D$14*$E$14/12) | BP27: =IF($D$14<=0,0,MIN($D$14+BO27,$F$14+BN27)) | BQ27: =IF($D$14<=0,BN27,MAX(0,$F$14+BN27-$D$14-BO27)) | BR27: =IF($D$15<=0,0,$D$15*$E$15/12) | BS27: =IF($D$15<=0,0,MIN($D$15+BR27,$F$15+BQ27)) | BT27: =IF($D$15<=0,BQ27,MAX(0,$F$15+BQ27-$D$15-BR27)) | BU27: =IF($D$16<=0,0,$D$16*$E$16/12) | BV27: =IF($D$16<=0,0,MIN($D$16+BU27,$F$16+BT27)) | BW27: =IF($D$16<=0,BT27,MAX(0,$F$16+BT27-$D$16-BU27)) | BX27: =IF($D$17<=0,0,$D$17*$E$17/12) | BY27: =IF($D$17<=0,0,MIN($D$17+BX27,$F$17+BW27)) | BZ27: =IF($D$17<=0,BW27,MAX(0,$F$17+BW27-$D$17-BX27)) | CA27: =IF($D$18<=0,0,$D$18*$E$18/12) | CB27: =IF($D$18<=0,0,MIN($D$18+CA27,$F$18+BZ27)) | CC27: =IF($D$18<=0,BZ27,MAX(0,$F$18+BZ27-$D$18-CA27)) | CD27: =IF($D$19<=0,0,$D$19*$E$19/12) | CE27: =IF($D$19<=0,0,MIN($D$19+CD27,$F$19+CC27)) | CF27: =IF($D$19<=0,CC27,MAX(0,$F$19+CC27-$D$19-CD27)) | CG27: =IF($D$20<=0,0,$D$20*$E$20/12) | CH27: =IF($D$20<=0,0,MIN($D$20+CG27,$F$20+CF27)) | CI27: =IF($D$20<=0,CF27,MAX(0,$F$20+CF27-$D$20-CG27)) | CJ27: =IF($D$21<=0,0,$D$21*$E$21/12) | CK27: =IF($D$21<=0,0,MIN($D$21+CJ27,$F$21+CI27)) | CL27: =IF($D$21<=0,CI27,MAX(0,$F$21+CI27-$D$21-CJ27)) | CM27: =IF($D$22<=0,0,$D$22*$E$22/12) | CN27: =IF($D$22<=0,0,MIN($D$22+CM27,$F$22+CL27)) | CO27: =IF($D$22<=0,CL27,MAX(0,$F$22+CL27-$D$22-CM27)) | CP27: =IF($D$23<=0,0,$D$23*$E$23/12) | CQ27: =IF($D$23<=0,0,MIN($D$23+CP27,$F$23+CO27)) | CR27: =IF($D$23<=0,CO27,MAX(0,$F$23+CO27-$D$23-CP27)) | CS27: =IF($D$24<=0,0,$D$24*$E$24/12) | CT27: =IF($D$24<=0,0,MIN($D$24+CS27,$F$24+CR27)) | CU27: =IF($D$24<=0,CR27,MAX(0,$F$24+CR27-$D$24-CS27))
B28: 2 | C28: =IF(C27<=0,0,MAX(0,C27+AN28-AO28)) | D28: =IF(D27<=0,0,MAX(0,D27+AQ28-AR28)) | E28: =IF(E27<=0,0,MAX(0,E27+AT28-AU28)) | F28: =IF(F27<=0,0,MAX(0,F27+AW28-AX28)) | G28: =IF(G27<=0,0,MAX(0,G27+AZ28-BA28)) | H28: =IF(H27<=0,0,MAX(0,H27+BC28-BD28)) | I28: =IF(I27<=0,0,MAX(0,I27+BF28-BG28)) | J28: =IF(J27<=0,0,MAX(0,J27+BI28-BJ28)) | K28: =IF(K27<=0,0,MAX(0,K27+BL28-BM28)) | L28: =IF(L27<=0,0,MAX(0,L27+BO28-BP28)) | M28: =IF(M27<=0,0,MAX(0,M27+BR28-BS28)) | N28: =IF(N27<=0,0,MAX(0,N27+BU28-BV28)) | O28: =IF(O27<=0,0,MAX(0,O27+BX28-BY28)) | P28: =IF(P27<=0,0,MAX(0,P27+CA28-CB28)) | Q28: =IF(Q27<=0,0,MAX(0,Q27+CD28-CE28)) | R28: =IF(R27<=0,0,MAX(0,R27+CG28-CH28)) | S28: =IF(S27<=0,0,MAX(0,S27+CJ28-CK28)) | T28: =IF(T27<=0,0,MAX(0,T27+CM28-CN28)) | U28: =IF(U27<=0,0,MAX(0,U27+CP28-CQ28)) | V28: =IF(V27<=0,0,MAX(0,V27+CS28-CT28)) | W28: =AO28+AR28+AU28+AX28+BA28+BD28+BG28+BJ28+BM28+BP28+BS28+BV28+BY28+CB28+CE28+CH28+CK28+CN28+CQ28+CT28 | X28: =AN28+AQ28+AT28+AW28+AZ28+BC28+BF28+BI28+BL28+BO28+BR28+BU28+BX28+CA28+CD28+CG28+CJ28+CM28+CP28+CS28 | Y28: =C28+D28+E28+F28+G28+H28+I28+J28+K28+L28+M28+N28+O28+P28+Q28+R28+S28+T28+U28+V28 | AN28: =IF(C27<=0,0,C27*$E$5/12) | AO28: =IF(C27<=0,0,MIN(C27+AN28,$F$5+(Dashboard!$C$11+IF(C27<=0,$F$5,0)+IF(D27<=0,$F$6,0)+IF(E27<=0,$F$7,0)+IF(F27<=0,$F$8,0)+IF(G27<=0,$F$9,0)+IF(H27<=0,$F$10,0)+IF(I27<=0,$F$11,0)+IF(J27<=0,$F$12,0)+IF(K27<=0,$F$13,0)+IF(L27<=0,$F$14,0)+IF(M27<=0,$F$15,0)+IF(N27<=0,$F$16,0)+IF(O27<=0,$F$17,0)+IF(P27<=0,$F$18,0)+IF(Q27<=0,$F$19,0)+IF(R27<=0,$F$20,0)+IF(S27<=0,$F$21,0)+IF(T27<=0,$F$22,0)+IF(U27<=0,$F$23,0)+IF(V27<=0,$F$24,0)))) | AP28: =IF(C27<=0,(Dashboard!$C$11+IF(C27<=0,$F$5,0)+IF(D27<=0,$F$6,0)+IF(E27<=0,$F$7,0)+IF(F27<=0,$F$8,0)+IF(G27<=0,$F$9,0)+IF(H27<=0,$F$10,0)+IF(I27<=0,$F$11,0)+IF(J27<=0,$F$12,0)+IF(K27<=0,$F$13,0)+IF(L27<=0,$F$14,0)+IF(M27<=0,$F$15,0)+IF(N27<=0,$F$16,0)+IF(O27<=0,$F$17,0)+IF(P27<=0,$F$18,0)+IF(Q27<=0,$F$19,0)+IF(R27<=0,$F$20,0)+IF(S27<=0,$F$21,0)+IF(T27<=0,$F$22,0)+IF(U27<=0,$F$23,0)+IF(V27<=0,$F$24,0)),MAX(0,$F$5+(Dashboard!$C$11+IF(C27<=0,$F$5,0)+IF(D27<=0,$F$6,0)+IF(E27<=0,$F$7,0)+IF(F27<=0,$F$8,0)+IF(G27<=0,$F$9,0)+IF(H27<=0,$F$10,0)+IF(I27<=0,$F$11,0)+IF(J27<=0,$F$12,0)+IF(K27<=0,$F$13,0)+IF(L27<=0,$F$14,0)+IF(M27<=0,$F$15,0)+IF(N27<=0,$F$16,0)+IF(O27<=0,$F$17,0)+IF(P27<=0,$F$18,0)+IF(Q27<=0,$F$19,0)+IF(R27<=0,$F$20,0)+IF(S27<=0,$F$21,0)+IF(T27<=0,$F$22,0)+IF(U27<=0,$F$23,0)+IF(V27<=0,$F$24,0))-C27-AN28)) | AQ28: =IF(D27<=0,0,D27*$E$6/12) | AR28: =IF(D27<=0,0,MIN(D27+AQ28,$F$6+AP28)) | AS28: =IF(D27<=0,AP28,MAX(0,$F$6+AP28-D27-AQ28)) | AT28: =IF(E27<=0,0,E27*$E$7/12) | AU28: =IF(E27<=0,0,MIN(E27+AT28,$F$7+AS28)) | AV28: =IF(E27<=0,AS28,MAX(0,$F$7+AS28-E27-AT28)) | AW28: =IF(F27<=0,0,F27*$E$8/12) | AX28: =IF(F27<=0,0,MIN(F27+AW28,$F$8+AV28)) | AY28: =IF(F27<=0,AV28,MAX(0,$F$8+AV28-F27-AW28)) | AZ28: =IF(G27<=0,0,G27*$E$9/12) | BA28: =IF(G27<=0,0,MIN(G27+AZ28,$F$9+AY28)) | BB28: =IF(G27<=0,AY28,MAX(0,$F$9+AY28-G27-AZ28)) | BC28: =IF(H27<=0,0,H27*$E$10/12) | BD28: =IF(H27<=0,0,MIN(H27+BC28,$F$10+BB28)) | BE28: =IF(H27<=0,BB28,MAX(0,$F$10+BB28-H27-BC28)) | BF28: =IF(I27<=0,0,I27*$E$11/12) | BG28: =IF(I27<=0,0,MIN(I27+BF28,$F$11+BE28)) | BH28: =IF(I27<=0,BE28,MAX(0,$F$11+BE28-I27-BF28)) | BI28: =IF(J27<=0,0,J27*$E$12/12) | BJ28: =IF(J27<=0,0,MIN(J27+BI28,$F$12+BH28)) | BK28: =IF(J27<=0,BH28,MAX(0,$F$12+BH28-J27-BI28)) | BL28: =IF(K27<=0,0,K27*$E$13/12) | BM28: =IF(K27<=0,0,MIN(K27+BL28,$F$13+BK28)) | BN28: =IF(K27<=0,BK28,MAX(0,$F$13+BK28-K27-BL28)) | BO28: =IF(L27<=0,0,L27*$E$14/12) | BP28: =IF(L27<=0,0,MIN(L27+BO28,$F$14+BN28)) | BQ28: =IF(L27<=0,BN28,MAX(0,$F$14+BN28-L27-BO28)) | BR28: =IF(M27<=0,0,M27*$E$15/12) | BS28: =IF(M27<=0,0,MIN(M27+BR28,$F$15+BQ28)) | BT28: =IF(M27<=0,BQ28,MAX(0,$F$15+BQ28-M27-BR28)) | BU28: =IF(N27<=0,0,N27*$E$16/12) | BV28: =IF(N27<=0,0,MIN(N27+BU28,$F$16+BT28)) | BW28: =IF(N27<=0,BT28,MAX(0,$F$16+BT28-N27-BU28)) | BX28: =IF(O27<=0,0,O27*$E$17/12) | BY28: =IF(O27<=0,0,MIN(O27+BX28,$F$17+BW28)) | BZ28: =IF(O27<=0,BW28,MAX(0,$F$17+BW28-O27-BX28)) | CA28: =IF(P27<=0,0,P27*$E$18/12) | CB28: =IF(P27<=0,0,MIN(P27+CA28,$F$18+BZ28)) | CC28: =IF(P27<=0,BZ28,MAX(0,$F$18+BZ28-P27-CA28)) | CD28: =IF(Q27<=0,0,Q27*$E$19/12) | CE28: =IF(Q27<=0,0,MIN(Q27+CD28,$F$19+CC28)) | CF28: =IF(Q27<=0,CC28,MAX(0,$F$19+CC28-Q27-CD28)) | CG28: =IF(R27<=0,0,R27*$E$20/12) | CH28: =IF(R27<=0,0,MIN(R27+CG28,$F$20+CF28)) | CI28: =IF(R27<=0,CF28,MAX(0,$F$20+CF28-R27-CG28)) | CJ28: =IF(S27<=0,0,S27*$E$21/12) | CK28: =IF(S27<=0,0,MIN(S27+CJ28,$F$21+CI28)) | CL28: =IF(S27<=0,CI28,MAX(0,$F$21+CI28-S27-CJ28)) | CM28: =IF(T27<=0,0,T27*$E$22/12) | CN28: =IF(T27<=0,0,MIN(T27+CM28,$F$22+CL28)) | CO28: =IF(T27<=0,CL28,MAX(0,$F$22+CL28-T27-CM28)) | CP28: =IF(U27<=0,0,U27*$E$23/12) | CQ28: =IF(U27<=0,0,MIN(U27+CP28,$F$23+CO28)) | CR28: =IF(U27<=0,CO28,MAX(0,$F$23+CO28-U27-CP28)) | CS28: =IF(V27<=0,0,V27*$E$24/12) | CT28: =IF(V27<=0,0,MIN(V27+CS28,$F$24+CR28)) | CU28: =IF(V27<=0,CR28,MAX(0,$F$24+CR28-V27-CS28))
B29: 3 | C29: =IF(C28<=0,0,MAX(0,C28+AN29-AO29)) | D29: =IF(D28<=0,0,MAX(0,D28+AQ29-AR29)) | E29: =IF(E28<=0,0,MAX(0,E28+AT29-AU29)) | F29: =IF(F28<=0,0,MAX(0,F28+AW29-AX29)) | G29: =IF(G28<=0,0,MAX(0,G28+AZ29-BA29)) | H29: =IF(H28<=0,0,MAX(0,H28+BC29-BD29)) | I29: =IF(I28<=0,0,MAX(0,I28+BF29-BG29)) | J29: =IF(J28<=0,0,MAX(0,J28+BI29-BJ29)) | K29: =IF(K28<=0,0,MAX(0,K28+BL29-BM29)) | L29: =IF(L28<=0,0,MAX(0,L28+BO29-BP29)) | M29: =IF(M28<=0,0,MAX(0,M28+BR29-BS29)) | N29: =IF(N28<=0,0,MAX(0,N28+BU29-BV29)) | O29: =IF(O28<=0,0,MAX(0,O28+BX29-BY29)) | P29: =IF(P28<=0,0,MAX(0,P28+CA29-CB29)) | Q29: =IF(Q28<=0,0,MAX(0,Q28+CD29-CE29)) | R29: =IF(R28<=0,0,MAX(0,R28+CG29-CH29)) | S29: =IF(S28<=0,0,MAX(0,S28+CJ29-CK29)) | T29: =IF(T28<=0,0,MAX(0,T28+CM29-CN29)) | U29: =IF(U28<=0,0,MAX(0,U28+CP29-CQ29)) | V29: =IF(V28<=0,0,MAX(0,V28+CS29-CT29)) | W29: =AO29+AR29+AU29+AX29+BA29+BD29+BG29+BJ29+BM29+BP29+BS29+BV29+BY29+CB29+CE29+CH29+CK29+CN29+CQ29+CT29 | X29: =AN29+AQ29+AT29+AW29+AZ29+BC29+BF29+BI29+BL29+BO29+BR29+BU29+BX29+CA29+CD29+CG29+CJ29+CM29+CP29+CS29 | Y29: =C29+D29+E29+F29+G29+H29+I29+J29+K29+L29+M29+N29+O29+P29+Q29+R29+S29+T29+U29+V29 | AN29: =IF(C28<=0,0,C28*$E$5/12) | AO29: =IF(C28<=0,0,MIN(C28+AN29,$F$5+(Dashboard!$C$11+IF(C28<=0,$F$5,0)+IF(D28<=0,$F$6,0)+IF(E28<=0,$F$7,0)+IF(F28<=0,$F$8,0)+IF(G28<=0,$F$9,0)+IF(H28<=0,$F$10,0)+IF(I28<=0,$F$11,0)+IF(J28<=0,$F$12,0)+IF(K28<=0,$F$13,0)+IF(L28<=0,$F$14,0)+IF(M28<=0,$F$15,0)+IF(N28<=0,$F$16,0)+IF(O28<=0,$F$17,0)+IF(P28<=0,$F$18,0)+IF(Q28<=0,$F$19,0)+IF(R28<=0,$F$20,0)+IF(S28<=0,$F$21,0)+IF(T28<=0,$F$22,0)+IF(U28<=0,$F$23,0)+IF(V28<=0,$F$24,0)))) | AP29: =IF(C28<=0,(Dashboard!$C$11+IF(C28<=0,$F$5,0)+IF(D28<=0,$F$6,0)+IF(E28<=0,$F$7,0)+IF(F28<=0,$F$8,0)+IF(G28<=0,$F$9,0)+IF(H28<=0,$F$10,0)+IF(I28<=0,$F$11,0)+IF(J28<=0,$F$12,0)+IF(K28<=0,$F$13,0)+IF(L28<=0,$F$14,0)+IF(M28<=0,$F$15,0)+IF(N28<=0,$F$16,0)+IF(O28<=0,$F$17,0)+IF(P28<=0,$F$18,0)+IF(Q28<=0,$F$19,0)+IF(R28<=0,$F$20,0)+IF(S28<=0,$F$21,0)+IF(T28<=0,$F$22,0)+IF(U28<=0,$F$23,0)+IF(V28<=0,$F$24,0)),MAX(0,$F$5+(Dashboard!$C$11+IF(C28<=0,$F$5,0)+IF(D28<=0,$F$6,0)+IF(E28<=0,$F$7,0)+IF(F28<=0,$F$8,0)+IF(G28<=0,$F$9,0)+IF(H28<=0,$F$10,0)+IF(I28<=0,$F$11,0)+IF(J28<=0,$F$12,0)+IF(K28<=0,$F$13,0)+IF(L28<=0,$F$14,0)+IF(M28<=0,$F$15,0)+IF(N28<=0,$F$16,0)+IF(O28<=0,$F$17,0)+IF(P28<=0,$F$18,0)+IF(Q28<=0,$F$19,0)+IF(R28<=0,$F$20,0)+IF(S28<=0,$F$21,0)+IF(T28<=0,$F$22,0)+IF(U28<=0,$F$23,0)+IF(V28<=0,$F$24,0))-C28-AN29)) | AQ29: =IF(D28<=0,0,D28*$E$6/12) | AR29: =IF(D28<=0,0,MIN(D28+AQ29,$F$6+AP29)) | AS29: =IF(D28<=0,AP29,MAX(0,$F$6+AP29-D28-AQ29)) | AT29: =IF(E28<=0,0,E28*$E$7/12) | AU29: =IF(E28<=0,0,MIN(E28+AT29,$F$7+AS29)) | AV29: =IF(E28<=0,AS29,MAX(0,$F$7+AS29-E28-AT29)) | AW29: =IF(F28<=0,0,F28*$E$8/12) | AX29: =IF(F28<=0,0,MIN(F28+AW29,$F$8+AV29)) | AY29: =IF(F28<=0,AV29,MAX(0,$F$8+AV29-F28-AW29)) | AZ29: =IF(G28<=0,0,G28*$E$9/12) | BA29: =IF(G28<=0,0,MIN(G28+AZ29,$F$9+AY29)) | BB29: =IF(G28<=0,AY29,MAX(0,$F$9+AY29-G28-AZ29)) | BC29: =IF(H28<=0,0,H28*$E$10/12) | BD29: =IF(H28<=0,0,MIN(H28+BC29,$F$10+BB29)) | BE29: =IF(H28<=0,BB29,MAX(0,$F$10+BB29-H28-BC29)) | BF29: =IF(I28<=0,0,I28*$E$11/12) | BG29: =IF(I28<=0,0,MIN(I28+BF29,$F$11+BE29)) | BH29: =IF(I28<=0,BE29,MAX(0,$F$11+BE29-I28-BF29)) | BI29: =IF(J28<=0,0,J28*$E$12/12) | BJ29: =IF(J28<=0,0,MIN(J28+BI29,$F$12+BH29)) | BK29: =IF(J28<=0,BH29,MAX(0,$F$12+BH29-J28-BI29)) | BL29: =IF(K28<=0,0,K28*$E$13/12) | BM29: =IF(K28<=0,0,MIN(K28+BL29,$F$13+BK29)) | BN29: =IF(K28<=0,BK29,MAX(0,$F$13+BK29-K28-BL29)) | BO29: =IF(L28<=0,0,L28*$E$14/12) | BP29: =IF(L28<=0,0,MIN(L28+BO29,$F$14+BN29)) | BQ29: =IF(L28<=0,BN29,MAX(0,$F$14+BN29-L28-BO29)) | BR29: =IF(M28<=0,0,M28*$E$15/12) | BS29: =IF(M28<=0,0,MIN(M28+BR29,$F$15+BQ29)) | BT29: =IF(M28<=0,BQ29,MAX(0,$F$15+BQ29-M28-BR29)) | BU29: =IF(N28<=0,0,N28*$E$16/12) | BV29: =IF(N28<=0,0,MIN(N28+BU29,$F$16+BT29)) | BW29: =IF(N28<=0,BT29,MAX(0,$F$16+BT29-N28-BU29)) | BX29: =IF(O28<=0,0,O28*$E$17/12) | BY29: =IF(O28<=0,0,MIN(O28+BX29,$F$17+BW29)) | BZ29: =IF(O28<=0,BW29,MAX(0,$F$17+BW29-O28-BX29)) | CA29: =IF(P28<=0,0,P28*$E$18/12) | CB29: =IF(P28<=0,0,MIN(P28+CA29,$F$18+BZ29)) | CC29: =IF(P28<=0,BZ29,MAX(0,$F$18+BZ29-P28-CA29)) | CD29: =IF(Q28<=0,0,Q28*$E$19/12) | CE29: =IF(Q28<=0,0,MIN(Q28+CD29,$F$19+CC29)) | CF29: =IF(Q28<=0,CC29,MAX(0,$F$19+CC29-Q28-CD29)) | CG29: =IF(R28<=0,0,R28*$E$20/12) | CH29: =IF(R28<=0,0,MIN(R28+CG29,$F$20+CF29)) | CI29: =IF(R28<=0,CF29,MAX(0,$F$20+CF29-R28-CG29)) | CJ29: =IF(S28<=0,0,S28*$E$21/12) | CK29: =IF(S28<=0,0,MIN(S28+CJ29,$F$21+CI29)) | CL29: =IF(S28<=0,CI29,MAX(0,$F$21+CI29-S28-CJ29)) | CM29: =IF(T28<=0,0,T28*$E$22/12) | CN29: =IF(T28<=0,0,MIN(T28+CM29,$F$22+CL29)) | CO29: =IF(T28<=0,CL29,MAX(0,$F$22+CL29-T28-CM29)) | CP29: =IF(U28<=0,0,U28*$E$23/12) | CQ29: =IF(U28<=0,0,MIN(U28+CP29,$F$23+CO29)) | CR29: =IF(U28<=0,CO29,MAX(0,$F$23+CO29-U28-CP29)) | CS29: =IF(V28<=0,0,V28*$E$24/12) | CT29: =IF(V28<=0,0,MIN(V28+CS29,$F$24+CR29)) | CU29: =IF(V28<=0,CR29,MAX(0,$F$24+CR29-V28-CS29))
B30: 4 | C30: =IF(C29<=0,0,MAX(0,C29+AN30-AO30)) | D30: =IF(D29<=0,0,MAX(0,D29+AQ30-AR30)) | E30: =IF(E29<=0,0,MAX(0,E29+AT30-AU30)) | F30: =IF(F29<=0,0,MAX(0,F29+AW30-AX30)) | G30: =IF(G29<=0,0,MAX(0,G29+AZ30-BA30)) | H30: =IF(H29<=0,0,MAX(0,H29+BC30-BD30)) | I30: =IF(I29<=0,0,MAX(0,I29+BF30-BG30)) | J30: =IF(J29<=0,0,MAX(0,J29+BI30-BJ30)) | K30: =IF(K29<=0,0,MAX(0,K29+BL30-BM30)) | L30: =IF(L29<=0,0,MAX(0,L29+BO30-BP30)) | M30: =IF(M29<=0,0,MAX(0,M29+BR30-BS30)) | N30: =IF(N29<=0,0,MAX(0,N29+BU30-BV30)) | O30: =IF(O29<=0,0,MAX(0,O29+BX30-BY30)) | P30: =IF(P29<=0,0,MAX(0,P29+CA30-CB30)) | Q30: =IF(Q29<=0,0,MAX(0,Q29+CD30-CE30)) | R30: =IF(R29<=0,0,MAX(0,R29+CG30-CH30)) | S30: =IF(S29<=0,0,MAX(0,S29+CJ30-CK30)) | T30: =IF(T29<=0,0,MAX(0,T29+CM30-CN30)) | U30: =IF(U29<=0,0,MAX(0,U29+CP30-CQ30)) | V30: =IF(V29<=0,0,MAX(0,V29+CS30-CT30)) | W30: =AO30+AR30+AU30+AX30+BA30+BD30+BG30+BJ30+BM30+BP30+BS30+BV30+BY30+CB30+CE30+CH30+CK30+CN30+CQ30+CT30 | X30: =AN30+AQ30+AT30+AW30+AZ30+BC30+BF30+BI30+BL30+BO30+BR30+BU30+BX30+CA30+CD30+CG30+CJ30+CM30+CP30+CS30 | Y30: =C30+D30+E30+F30+G30+H30+I30+J30+K30+L30+M30+N30+O30+P30+Q30+R30+S30+T30+U30+V30 | AN30: =IF(C29<=0,0,C29*$E$5/12) | AO30: =IF(C29<=0,0,MIN(C29+AN30,$F$5+(Dashboard!$C$11+IF(C29<=0,$F$5,0)+IF(D29<=0,$F$6,0)+IF(E29<=0,$F$7,0)+IF(F29<=0,$F$8,0)+IF(G29<=0,$F$9,0)+IF(H29<=0,$F$10,0)+IF(I29<=0,$F$11,0)+IF(J29<=0,$F$12,0)+IF(K29<=0,$F$13,0)+IF(L29<=0,$F$14,0)+IF(M29<=0,$F$15,0)+IF(N29<=0,$F$16,0)+IF(O29<=0,$F$17,0)+IF(P29<=0,$F$18,0)+IF(Q29<=0,$F$19,0)+IF(R29<=0,$F$20,0)+IF(S29<=0,$F$21,0)+IF(T29<=0,$F$22,0)+IF(U29<=0,$F$23,0)+IF(V29<=0,$F$24,0)))) | AP30: =IF(C29<=0,(Dashboard!$C$11+IF(C29<=0,$F$5,0)+IF(D29<=0,$F$6,0)+IF(E29<=0,$F$7,0)+IF(F29<=0,$F$8,0)+IF(G29<=0,$F$9,0)+IF(H29<=0,$F$10,0)+IF(I29<=0,$F$11,0)+IF(J29<=0,$F$12,0)+IF(K29<=0,$F$13,0)+IF(L29<=0,$F$14,0)+IF(M29<=0,$F$15,0)+IF(N29<=0,$F$16,0)+IF(O29<=0,$F$17,0)+IF(P29<=0,$F$18,0)+IF(Q29<=0,$F$19,0)+IF(R29<=0,$F$20,0)+IF(S29<=0,$F$21,0)+IF(T29<=0,$F$22,0)+IF(U29<=0,$F$23,0)+IF(V29<=0,$F$24,0)),MAX(0,$F$5+(Dashboard!$C$11+IF(C29<=0,$F$5,0)+IF(D29<=0,$F$6,0)+IF(E29<=0,$F$7,0)+IF(F29<=0,$F$8,0)+IF(G29<=0,$F$9,0)+IF(H29<=0,$F$10,0)+IF(I29<=0,$F$11,0)+IF(J29<=0,$F$12,0)+IF(K29<=0,$F$13,0)+IF(L29<=0,$F$14,0)+IF(M29<=0,$F$15,0)+IF(N29<=0,$F$16,0)+IF(O29<=0,$F$17,0)+IF(P29<=0,$F$18,0)+IF(Q29<=0,$F$19,0)+IF(R29<=0,$F$20,0)+IF(S29<=0,$F$21,0)+IF(T29<=0,$F$22,0)+IF(U29<=0,$F$23,0)+IF(V29<=0,$F$24,0))-C29-AN30)) | AQ30: =IF(D29<=0,0,D29*$E$6/12) | AR30: =IF(D29<=0,0,MIN(D29+AQ30,$F$6+AP30)) | AS30: =IF(D29<=0,AP30,MAX(0,$F$6+AP30-D29-AQ30)) | AT30: =IF(E29<=0,0,E29*$E$7/12) | AU30: =IF(E29<=0,0,MIN(E29+AT30,$F$7+AS30)) | AV30: =IF(E29<=0,AS30,MAX(0,$F$7+AS30-E29-AT30)) | AW30: =IF(F29<=0,0,F29*$E$8/12) | AX30: =IF(F29<=0,0,MIN(F29+AW30,$F$8+AV30)) | AY30: =IF(F29<=0,AV30,MAX(0,$F$8+AV30-F29-AW30)) | AZ30: =IF(G29<=0,0,G29*$E$9/12) | BA30: =IF(G29<=0,0,MIN(G29+AZ30,$F$9+AY30)) | BB30: =IF(G29<=0,AY30,MAX(0,$F$9+AY30-G29-AZ30)) | BC30: =IF(H29<=0,0,H29*$E$10/12) | BD30: =IF(H29<=0,0,MIN(H29+BC30,$F$10+BB30)) | BE30: =IF(H29<=0,BB30,MAX(0,$F$10+BB30-H29-BC30)) | BF30: =IF(I29<=0,0,I29*$E$11/12) | BG30: =IF(I29<=0,0,MIN(I29+BF30,$F$11+BE30)) | BH30: =IF(I29<=0,BE30,MAX(0,$F$11+BE30-I29-BF30)) | BI30: =IF(J29<=0,0,J29*$E$12/12) | BJ30: =IF(J29<=0,0,MIN(J29+BI30,$F$12+BH30)) | BK30: =IF(J29<=0,BH30,MAX(0,$F$12+BH30-J29-BI30)) | BL30: =IF(K29<=0,0,K29*$E$13/12) | BM30: =IF(K29<=0,0,MIN(K29+BL30,$F$13+BK30)) | BN30: =IF(K29<=0,BK30,MAX(0,$F$13+BK30-K29-BL30)) | BO30: =IF(L29<=0,0,L29*$E$14/12) | BP30: =IF(L29<=0,0,MIN(L29+BO30,$F$14+BN30)) | BQ30: =IF(L29<=0,BN30,MAX(0,$F$14+BN30-L29-BO30)) | BR30: =IF(M29<=0,0,M29*$E$15/12) | BS30: =IF(M29<=0,0,MIN(M29+BR30,$F$15+BQ30)) | BT30: =IF(M29<=0,BQ30,MAX(0,$F$15+BQ30-M29-BR30)) | BU30: =IF(N29<=0,0,N29*$E$16/12) | BV30: =IF(N29<=0,0,MIN(N29+BU30,$F$16+BT30)) | BW30: =IF(N29<=0,BT30,MAX(0,$F$16+BT30-N29-BU30)) | BX30: =IF(O29<=0,0,O29*$E$17/12) | BY30: =IF(O29<=0,0,MIN(O29+BX30,$F$17+BW30)) | BZ30: =IF(O29<=0,BW30,MAX(0,$F$17+BW30-O29-BX30)) | CA30: =IF(P29<=0,0,P29*$E$18/12) | CB30: =IF(P29<=0,0,MIN(P29+CA30,$F$18+BZ30)) | CC30: =IF(P29<=0,BZ30,MAX(0,$F$18+BZ30-P29-CA30)) | CD30: =IF(Q29<=0,0,Q29*$E$19/12) | CE30: =IF(Q29<=0,0,MIN(Q29+CD30,$F$19+CC30)) | CF30: =IF(Q29<=0,CC30,MAX(0,$F$19+CC30-Q29-CD30)) | CG30: =IF(R29<=0,0,R29*$E$20/12) | CH30: =IF(R29<=0,0,MIN(R29+CG30,$F$20+CF30)) | CI30: =IF(R29<=0,CF30,MAX(0,$F$20+CF30-R29-CG30)) | CJ30: =IF(S29<=0,0,S29*$E$21/12) | CK30: =IF(S29<=0,0,MIN(S29+CJ30,$F$21+CI30)) | CL30: =IF(S29<=0,CI30,MAX(0,$F$21+CI30-S29-CJ30)) | CM30: =IF(T29<=0,0,T29*$E$22/12) | CN30: =IF(T29<=0,0,MIN(T29+CM30,$F$22+CL30)) | CO30: =IF(T29<=0,CL30,MAX(0,$F$22+CL30-T29-CM30)) | CP30: =IF(U29<=0,0,U29*$E$23/12) | CQ30: =IF(U29<=0,0,MIN(U29+CP30,$F$23+CO30)) | CR30: =IF(U29<=0,CO30,MAX(0,$F$23+CO30-U29-CP30)) | CS30: =IF(V29<=0,0,V29*$E$24/12) | CT30: =IF(V29<=0,0,MIN(V29+CS30,$F$24+CR30)) | CU30: =IF(V29<=0,CR30,MAX(0,$F$24+CR30-V29-CS30))
B31: 5 | C31: =IF(C30<=0,0,MAX(0,C30+AN31-AO31)) | D31: =IF(D30<=0,0,MAX(0,D30+AQ31-AR31)) | E31: =IF(E30<=0,0,MAX(0,E30+AT31-AU31)) | F31: =IF(F30<=0,0,MAX(0,F30+AW31-AX31)) | G31: =IF(G30<=0,0,MAX(0,G30+AZ31-BA31)) | H31: =IF(H30<=0,0,MAX(0,H30+BC31-BD31)) | I31: =IF(I30<=0,0,MAX(0,I30+BF31-BG31)) | J31: =IF(J30<=0,0,MAX(0,J30+BI31-BJ31)) | K31: =IF(K30<=0,0,MAX(0,K30+BL31-BM31)) | L31: =IF(L30<=0,0,MAX(0,L30+BO31-BP31)) | M31: =IF(M30<=0,0,MAX(0,M30+BR31-BS31)) | N31: =IF(N30<=0,0,MAX(0,N30+BU31-BV31)) | O31: =IF(O30<=0,0,MAX(0,O30+BX31-BY31)) | P31: =IF(P30<=0,0,MAX(0,P30+CA31-CB31)) | Q31: =IF(Q30<=0,0,MAX(0,Q30+CD31-CE31)) | R31: =IF(R30<=0,0,MAX(0,R30+CG31-CH31)) | S31: =IF(S30<=0,0,MAX(0,S30+CJ31-CK31)) | T31: =IF(T30<=0,0,MAX(0,T30+CM31-CN31)) | U31: =IF(U30<=0,0,MAX(0,U30+CP31-CQ31)) | V31: =IF(V30<=0,0,MAX(0,V30+CS31-CT31)) | W31: =AO31+AR31+AU31+AX31+BA31+BD31+BG31+BJ31+BM31+BP31+BS31+BV31+BY31+CB31+CE31+CH31+CK31+CN31+CQ31+CT31 | X31: =AN31+AQ31+AT31+AW31+AZ31+BC31+BF31+BI31+BL31+BO31+BR31+BU31+BX31+CA31+CD31+CG31+CJ31+CM31+CP31+CS31 | Y31: =C31+D31+E31+F31+G31+H31+I31+J31+K31+L31+M31+N31+O31+P31+Q31+R31+S31+T31+U31+V31 | AN31: =IF(C30<=0,0,C30*$E$5/12) | AO31: =IF(C30<=0,0,MIN(C30+AN31,$F$5+(Dashboard!$C$11+IF(C30<=0,$F$5,0)+IF(D30<=0,$F$6,0)+IF(E30<=0,$F$7,0)+IF(F30<=0,$F$8,0)+IF(G30<=0,$F$9,0)+IF(H30<=0,$F$10,0)+IF(I30<=0,$F$11,0)+IF(J30<=0,$F$12,0)+IF(K30<=0,$F$13,0)+IF(L30<=0,$F$14,0)+IF(M30<=0,$F$15,0)+IF(N30<=0,$F$16,0)+IF(O30<=0,$F$17,0)+IF(P30<=0,$F$18,0)+IF(Q30<=0,$F$19,0)+IF(R30<=0,$F$20,0)+IF(S30<=0,$F$21,0)+IF(T30<=0,$F$22,0)+IF(U30<=0,$F$23,0)+IF(V30<=0,$F$24,0)))) | AP31: =IF(C30<=0,(Dashboard!$C$11+IF(C30<=0,$F$5,0)+IF(D30<=0,$F$6,0)+IF(E30<=0,$F$7,0)+IF(F30<=0,$F$8,0)+IF(G30<=0,$F$9,0)+IF(H30<=0,$F$10,0)+IF(I30<=0,$F$11,0)+IF(J30<=0,$F$12,0)+IF(K30<=0,$F$13,0)+IF(L30<=0,$F$14,0)+IF(M30<=0,$F$15,0)+IF(N30<=0,$F$16,0)+IF(O30<=0,$F$17,0)+IF(P30<=0,$F$18,0)+IF(Q30<=0,$F$19,0)+IF(R30<=0,$F$20,0)+IF(S30<=0,$F$21,0)+IF(T30<=0,$F$22,0)+IF(U30<=0,$F$23,0)+IF(V30<=0,$F$24,0)),MAX(0,$F$5+(Dashboard!$C$11+IF(C30<=0,$F$5,0)+IF(D30<=0,$F$6,0)+IF(E30<=0,$F$7,0)+IF(F30<=0,$F$8,0)+IF(G30<=0,$F$9,0)+IF(H30<=0,$F$10,0)+IF(I30<=0,$F$11,0)+IF(J30<=0,$F$12,0)+IF(K30<=0,$F$13,0)+IF(L30<=0,$F$14,0)+IF(M30<=0,$F$15,0)+IF(N30<=0,$F$16,0)+IF(O30<=0,$F$17,0)+IF(P30<=0,$F$18,0)+IF(Q30<=0,$F$19,0)+IF(R30<=0,$F$20,0)+IF(S30<=0,$F$21,0)+IF(T30<=0,$F$22,0)+IF(U30<=0,$F$23,0)+IF(V30<=0,$F$24,0))-C30-AN31)) | AQ31: =IF(D30<=0,0,D30*$E$6/12) | AR31: =IF(D30<=0,0,MIN(D30+AQ31,$F$6+AP31)) | AS31: =IF(D30<=0,AP31,MAX(0,$F$6+AP31-D30-AQ31)) | AT31: =IF(E30<=0,0,E30*$E$7/12) | AU31: =IF(E30<=0,0,MIN(E30+AT31,$F$7+AS31)) | AV31: =IF(E30<=0,AS31,MAX(0,$F$7+AS31-E30-AT31)) | AW31: =IF(F30<=0,0,F30*$E$8/12) | AX31: =IF(F30<=0,0,MIN(F30+AW31,$F$8+AV31)) | AY31: =IF(F30<=0,AV31,MAX(0,$F$8+AV31-F30-AW31)) | AZ31: =IF(G30<=0,0,G30*$E$9/12) | BA31: =IF(G30<=0,0,MIN(G30+AZ31,$F$9+AY31)) | BB31: =IF(G30<=0,AY31,MAX(0,$F$9+AY31-G30-AZ31)) | BC31: =IF(H30<=0,0,H30*$E$10/12) | BD31: =IF(H30<=0,0,MIN(H30+BC31,$F$10+BB31)) | BE31: =IF(H30<=0,BB31,MAX(0,$F$10+BB31-H30-BC31)) | BF31: =IF(I30<=0,0,I30*$E$11/12) | BG31: =IF(I30<=0,0,MIN(I30+BF31,$F$11+BE31)) | BH31: =IF(I30<=0,BE31,MAX(0,$F$11+BE31-I30-BF31)) | BI31: =IF(J30<=0,0,J30*$E$12/12) | BJ31: =IF(J30<=0,0,MIN(J30+BI31,$F$12+BH31)) | BK31: =IF(J30<=0,BH31,MAX(0,$F$12+BH31-J30-BI31)) | BL31: =IF(K30<=0,0,K30*$E$13/12) | BM31: =IF(K30<=0,0,MIN(K30+BL31,$F$13+BK31)) | BN31: =IF(K30<=0,BK31,MAX(0,$F$13+BK31-K30-BL31)) | BO31: =IF(L30<=0,0,L30*$E$14/12) | BP31: =IF(L30<=0,0,MIN(L30+BO31,$F$14+BN31)) | BQ31: =IF(L30<=0,BN31,MAX(0,$F$14+BN31-L30-BO31)) | BR31: =IF(M30<=0,0,M30*$E$15/12) | BS31: =IF(M30<=0,0,MIN(M30+BR31,$F$15+BQ31)) | BT31: =IF(M30<=0,BQ31,MAX(0,$F$15+BQ31-M30-BR31)) | BU31: =IF(N30<=0,0,N30*$E$16/12) | BV31: =IF(N30<=0,0,MIN(N30+BU31,$F$16+BT31)) | BW31: =IF(N30<=0,BT31,MAX(0,$F$16+BT31-N30-BU31)) | BX31: =IF(O30<=0,0,O30*$E$17/12) | BY31: =IF(O30<=0,0,MIN(O30+BX31,$F$17+BW31)) | BZ31: =IF(O30<=0,BW31,MAX(0,$F$17+BW31-O30-BX31)) | CA31: =IF(P30<=0,0,P30*$E$18/12) | CB31: =IF(P30<=0,0,MIN(P30+CA31,$F$18+BZ31)) | CC31: =IF(P30<=0,BZ31,MAX(0,$F$18+BZ31-P30-CA31)) | CD31: =IF(Q30<=0,0,Q30*$E$19/12) | CE31: =IF(Q30<=0,0,MIN(Q30+CD31,$F$19+CC31)) | CF31: =IF(Q30<=0,CC31,MAX(0,$F$19+CC31-Q30-CD31)) | CG31: =IF(R30<=0,0,R30*$E$20/12) | CH31: =IF(R30<=0,0,MIN(R30+CG31,$F$20+CF31)) | CI31: =IF(R30<=0,CF31,MAX(0,$F$20+CF31-R30-CG31)) | CJ31: =IF(S30<=0,0,S30*$E$21/12) | CK31: =IF(S30<=0,0,MIN(S30+CJ31,$F$21+CI31)) | CL31: =IF(S30<=0,CI31,MAX(0,$F$21+CI31-S30-CJ31)) | CM31: =IF(T30<=0,0,T30*$E$22/12) | CN31: =IF(T30<=0,0,MIN(T30+CM31,$F$22+CL31)) | CO31: =IF(T30<=0,CL31,MAX(0,$F$22+CL31-T30-CM31)) | CP31: =IF(U30<=0,0,U30*$E$23/12) | CQ31: =IF(U30<=0,0,MIN(U30+CP31,$F$23+CO31)) | CR31: =IF(U30<=0,CO31,MAX(0,$F$23+CO31-U30-CP31)) | CS31: =IF(V30<=0,0,V30*$E$24/12) | CT31: =IF(V30<=0,0,MIN(V30+CS31,$F$24+CR31)) | CU31: =IF(V30<=0,CR31,MAX(0,$F$24+CR31-V30-CS31))
B32: 6 | C32: =IF(C31<=0,0,MAX(0,C31+AN32-AO32)) | D32: =IF(D31<=0,0,MAX(0,D31+AQ32-AR32)) | E32: =IF(E31<=0,0,MAX(0,E31+AT32-AU32)) | F32: =IF(F31<=0,0,MAX(0,F31+AW32-AX32)) | G32: =IF(G31<=0,0,MAX(0,G31+AZ32-BA32)) | H32: =IF(H31<=0,0,MAX(0,H31+BC32-BD32)) | I32: =IF(I31<=0,0,MAX(0,I31+BF32-BG32)) | J32: =IF(J31<=0,0,MAX(0,J31+BI32-BJ32)) | K32: =IF(K31<=0,0,MAX(0,K31+BL32-BM32)) | L32: =IF(L31<=0,0,MAX(0,L31+BO32-BP32)) | M32: =IF(M31<=0,0,MAX(0,M31+BR32-BS32)) | N32: =IF(N31<=0,0,MAX(0,N31+BU32-BV32)) | O32: =IF(O31<=0,0,MAX(0,O31+BX32-BY32)) | P32: =IF(P31<=0,0,MAX(0,P31+CA32-CB32)) | Q32: =IF(Q31<=0,0,MAX(0,Q31+CD32-CE32)) | R32: =IF(R31<=0,0,MAX(0,R31+CG32-CH32)) | S32: =IF(S31<=0,0,MAX(0,S31+CJ32-CK32)) | T32: =IF(T31<=0,0,MAX(0,T31+CM32-CN32)) | U32: =IF(U31<=0,0,MAX(0,U31+CP32-CQ32)) | V32: =IF(V31<=0,0,MAX(0,V31+CS32-CT32)) | W32: =AO32+AR32+AU32+AX32+BA32+BD32+BG32+BJ32+BM32+BP32+BS32+BV32+BY32+CB32+CE32+CH32+CK32+CN32+CQ32+CT32 | X32: =AN32+AQ32+AT32+AW32+AZ32+BC32+BF32+BI32+BL32+BO32+BR32+BU32+BX32+CA32+CD32+CG32+CJ32+CM32+CP32+CS32 | Y32: =C32+D32+E32+F32+G32+H32+I32+J32+K32+L32+M32+N32+O32+P32+Q32+R32+S32+T32+U32+V32 | AN32: =IF(C31<=0,0,C31*$E$5/12) | AO32: =IF(C31<=0,0,MIN(C31+AN32,$F$5+(Dashboard!$C$11+IF(C31<=0,$F$5,0)+IF(D31<=0,$F$6,0)+IF(E31<=0,$F$7,0)+IF(F31<=0,$F$8,0)+IF(G31<=0,$F$9,0)+IF(H31<=0,$F$10,0)+IF(I31<=0,$F$11,0)+IF(J31<=0,$F$12,0)+IF(K31<=0,$F$13,0)+IF(L31<=0,$F$14,0)+IF(M31<=0,$F$15,0)+IF(N31<=0,$F$16,0)+IF(O31<=0,$F$17,0)+IF(P31<=0,$F$18,0)+IF(Q31<=0,$F$19,0)+IF(R31<=0,$F$20,0)+IF(S31<=0,$F$21,0)+IF(T31<=0,$F$22,0)+IF(U31<=0,$F$23,0)+IF(V31<=0,$F$24,0)))) | AP32: =IF(C31<=0,(Dashboard!$C$11+IF(C31<=0,$F$5,0)+IF(D31<=0,$F$6,0)+IF(E31<=0,$F$7,0)+IF(F31<=0,$F$8,0)+IF(G31<=0,$F$9,0)+IF(H31<=0,$F$10,0)+IF(I31<=0,$F$11,0)+IF(J31<=0,$F$12,0)+IF(K31<=0,$F$13,0)+IF(L31<=0,$F$14,0)+IF(M31<=0,$F$15,0)+IF(N31<=0,$F$16,0)+IF(O31<=0,$F$17,0)+IF(P31<=0,$F$18,0)+IF(Q31<=0,$F$19,0)+IF(R31<=0,$F$20,0)+IF(S31<=0,$F$21,0)+IF(T31<=0,$F$22,0)+IF(U31<=0,$F$23,0)+IF(V31<=0,$F$24,0)),MAX(0,$F$5+(Dashboard!$C$11+IF(C31<=0,$F$5,0)+IF(D31<=0,$F$6,0)+IF(E31<=0,$F$7,0)+IF(F31<=0,$F$8,0)+IF(G31<=0,$F$9,0)+IF(H31<=0,$F$10,0)+IF(I31<=0,$F$11,0)+IF(J31<=0,$F$12,0)+IF(K31<=0,$F$13,0)+IF(L31<=0,$F$14,0)+IF(M31<=0,$F$15,0)+IF(N31<=0,$F$16,0)+IF(O31<=0,$F$17,0)+IF(P31<=0,$F$18,0)+IF(Q31<=0,$F$19,0)+IF(R31<=0,$F$20,0)+IF(S31<=0,$F$21,0)+IF(T31<=0,$F$22,0)+IF(U31<=0,$F$23,0)+IF(V31<=0,$F$24,0))-C31-AN32)) | AQ32: =IF(D31<=0,0,D31*$E$6/12) | AR32: =IF(D31<=0,0,MIN(D31+AQ32,$F$6+AP32)) | AS32: =IF(D31<=0,AP32,MAX(0,$F$6+AP32-D31-AQ32)) | AT32: =IF(E31<=0,0,E31*$E$7/12) | AU32: =IF(E31<=0,0,MIN(E31+AT32,$F$7+AS32)) | AV32: =IF(E31<=0,AS32,MAX(0,$F$7+AS32-E31-AT32)) | AW32: =IF(F31<=0,0,F31*$E$8/12) | AX32: =IF(F31<=0,0,MIN(F31+AW32,$F$8+AV32)) | AY32: =IF(F31<=0,AV32,MAX(0,$F$8+AV32-F31-AW32)) | AZ32: =IF(G31<=0,0,G31*$E$9/12) | BA32: =IF(G31<=0,0,MIN(G31+AZ32,$F$9+AY32)) | BB32: =IF(G31<=0,AY32,MAX(0,$F$9+AY32-G31-AZ32)) | BC32: =IF(H31<=0,0,H31*$E$10/12) | BD32: =IF(H31<=0,0,MIN(H31+BC32,$F$10+BB32)) | BE32: =IF(H31<=0,BB32,MAX(0,$F$10+BB32-H31-BC32)) | BF32: =IF(I31<=0,0,I31*$E$11/12) | BG32: =IF(I31<=0,0,MIN(I31+BF32,$F$11+BE32)) | BH32: =IF(I31<=0,BE32,MAX(0,$F$11+BE32-I31-BF32)) | BI32: =IF(J31<=0,0,J31*$E$12/12) | BJ32: =IF(J31<=0,0,MIN(J31+BI32,$F$12+BH32)) | BK32: =IF(J31<=0,BH32,MAX(0,$F$12+BH32-J31-BI32)) | BL32: =IF(K31<=0,0,K31*$E$13/12) | BM32: =IF(K31<=0,0,MIN(K31+BL32,$F$13+BK32)) | BN32: =IF(K31<=0,BK32,MAX(0,$F$13+BK32-K31-BL32)) | BO32: =IF(L31<=0,0,L31*$E$14/12) | BP32: =IF(L31<=0,0,MIN(L31+BO32,$F$14+BN32)) | BQ32: =IF(L31<=0,BN32,MAX(0,$F$14+BN32-L31-BO32)) | BR32: =IF(M31<=0,0,M31*$E$15/12) | BS32: =IF(M31<=0,0,MIN(M31+BR32,$F$15+BQ32)) | BT32: =IF(M31<=0,BQ32,MAX(0,$F$15+BQ32-M31-BR32)) | BU32: =IF(N31<=0,0,N31*$E$16/12) | BV32: =IF(N31<=0,0,MIN(N31+BU32,$F$16+BT32)) | BW32: =IF(N31<=0,BT32,MAX(0,$F$16+BT32-N31-BU32)) | BX32: =IF(O31<=0,0,O31*$E$17/12) | BY32: =IF(O31<=0,0,MIN(O31+BX32,$F$17+BW32)) | BZ32: =IF(O31<=0,BW32,MAX(0,$F$17+BW32-O31-BX32)) | CA32: =IF(P31<=0,0,P31*$E$18/12) | CB32: =IF(P31<=0,0,MIN(P31+CA32,$F$18+BZ32)) | CC32: =IF(P31<=0,BZ32,MAX(0,$F$18+BZ32-P31-CA32)) | CD32: =IF(Q31<=0,0,Q31*$E$19/12) | CE32: =IF(Q31<=0,0,MIN(Q31+CD32,$F$19+CC32)) | CF32: =IF(Q31<=0,CC32,MAX(0,$F$19+CC32-Q31-CD32)) | CG32: =IF(R31<=0,0,R31*$E$20/12) | CH32: =IF(R31<=0,0,MIN(R31+CG32,$F$20+CF32)) | CI32: =IF(R31<=0,CF32,MAX(0,$F$20+CF32-R31-CG32)) | CJ32: =IF(S31<=0,0,S31*$E$21/12) | CK32: =IF(S31<=0,0,MIN(S31+CJ32,$F$21+CI32)) | CL32: =IF(S31<=0,CI32,MAX(0,$F$21+CI32-S31-CJ32)) | CM32: =IF(T31<=0,0,T31*$E$22/12) | CN32: =IF(T31<=0,0,MIN(T31+CM32,$F$22+CL32)) | CO32: =IF(T31<=0,CL32,MAX(0,$F$22+CL32-T31-CM32)) | CP32: =IF(U31<=0,0,U31*$E$23/12) | CQ32: =IF(U31<=0,0,MIN(U31+CP32,$F$23+CO32)) | CR32: =IF(U31<=0,CO32,MAX(0,$F$23+CO32-U31-CP32)) | CS32: =IF(V31<=0,0,V31*$E$24/12) | CT32: =IF(V31<=0,0,MIN(V31+CS32,$F$24+CR32)) | CU32: =IF(V31<=0,CR32,MAX(0,$F$24+CR32-V31-CS32))
B33: 7 | C33: =IF(C32<=0,0,MAX(0,C32+AN33-AO33)) | D33: =IF(D32<=0,0,MAX(0,D32+AQ33-AR33)) | E33: =IF(E32<=0,0,MAX(0,E32+AT33-AU33)) | F33: =IF(F32<=0,0,MAX(0,F32+AW33-AX33)) | G33: =IF(G32<=0,0,MAX(0,G32+AZ33-BA33)) | H33: =IF(H32<=0,0,MAX(0,H32+BC33-BD33)) | I33: =IF(I32<=0,0,MAX(0,I32+BF33-BG33)) | J33: =IF(J32<=0,0,MAX(0,J32+BI33-BJ33)) | K33: =IF(K32<=0,0,MAX(0,K32+BL33-BM33)) | L33: =IF(L32<=0,0,MAX(0,L32+BO33-BP33)) | M33: =IF(M32<=0,0,MAX(0,M32+BR33-BS33)) | N33: =IF(N32<=0,0,MAX(0,N32+BU33-BV33)) | O33: =IF(O32<=0,0,MAX(0,O32+BX33-BY33)) | P33: =IF(P32<=0,0,MAX(0,P32+CA33-CB33)) | Q33: =IF(Q32<=0,0,MAX(0,Q32+CD33-CE33)) | R33: =IF(R32<=0,0,MAX(0,R32+CG33-CH33)) | S33: =IF(S32<=0,0,MAX(0,S32+CJ33-CK33)) | T33: =IF(T32<=0,0,MAX(0,T32+CM33-CN33)) | U33: =IF(U32<=0,0,MAX(0,U32+CP33-CQ33)) | V33: =IF(V32<=0,0,MAX(0,V32+CS33-CT33)) | W33: =AO33+AR33+AU33+AX33+BA33+BD33+BG33+BJ33+BM33+BP33+BS33+BV33+BY33+CB33+CE33+CH33+CK33+CN33+CQ33+CT33 | X33: =AN33+AQ33+AT33+AW33+AZ33+BC33+BF33+BI33+BL33+BO33+BR33+BU33+BX33+CA33+CD33+CG33+CJ33+CM33+CP33+CS33 | Y33: =C33+D33+E33+F33+G33+H33+I33+J33+K33+L33+M33+N33+O33+P33+Q33+R33+S33+T33+U33+V33 | AN33: =IF(C32<=0,0,C32*$E$5/12) | AO33: =IF(C32<=0,0,MIN(C32+AN33,$F$5+(Dashboard!$C$11+IF(C32<=0,$F$5,0)+IF(D32<=0,$F$6,0)+IF(E32<=0,$F$7,0)+IF(F32<=0,$F$8,0)+IF(G32<=0,$F$9,0)+IF(H32<=0,$F$10,0)+IF(I32<=0,$F$11,0)+IF(J32<=0,$F$12,0)+IF(K32<=0,$F$13,0)+IF(L32<=0,$F$14,0)+IF(M32<=0,$F$15,0)+IF(N32<=0,$F$16,0)+IF(O32<=0,$F$17,0)+IF(P32<=0,$F$18,0)+IF(Q32<=0,$F$19,0)+IF(R32<=0,$F$20,0)+IF(S32<=0,$F$21,0)+IF(T32<=0,$F$22,0)+IF(U32<=0,$F$23,0)+IF(V32<=0,$F$24,0)))) | AP33: =IF(C32<=0,(Dashboard!$C$11+IF(C32<=0,$F$5,0)+IF(D32<=0,$F$6,0)+IF(E32<=0,$F$7,0)+IF(F32<=0,$F$8,0)+IF(G32<=0,$F$9,0)+IF(H32<=0,$F$10,0)+IF(I32<=0,$F$11,0)+IF(J32<=0,$F$12,0)+IF(K32<=0,$F$13,0)+IF(L32<=0,$F$14,0)+IF(M32<=0,$F$15,0)+IF(N32<=0,$F$16,0)+IF(O32<=0,$F$17,0)+IF(P32<=0,$F$18,0)+IF(Q32<=0,$F$19,0)+IF(R32<=0,$F$20,0)+IF(S32<=0,$F$21,0)+IF(T32<=0,$F$22,0)+IF(U32<=0,$F$23,0)+IF(V32<=0,$F$24,0)),MAX(0,$F$5+(Dashboard!$C$11+IF(C32<=0,$F$5,0)+IF(D32<=0,$F$6,0)+IF(E32<=0,$F$7,0)+IF(F32<=0,$F$8,0)+IF(G32<=0,$F$9,0)+IF(H32<=0,$F$10,0)+IF(I32<=0,$F$11,0)+IF(J32<=0,$F$12,0)+IF(K32<=0,$F$13,0)+IF(L32<=0,$F$14,0)+IF(M32<=0,$F$15,0)+IF(N32<=0,$F$16,0)+IF(O32<=0,$F$17,0)+IF(P32<=0,$F$18,0)+IF(Q32<=0,$F$19,0)+IF(R32<=0,$F$20,0)+IF(S32<=0,$F$21,0)+IF(T32<=0,$F$22,0)+IF(U32<=0,$F$23,0)+IF(V32<=0,$F$24,0))-C32-AN33)) | AQ33: =IF(D32<=0,0,D32*$E$6/12) | AR33: =IF(D32<=0,0,MIN(D32+AQ33,$F$6+AP33)) | AS33: =IF(D32<=0,AP33,MAX(0,$F$6+AP33-D32-AQ33)) | AT33: =IF(E32<=0,0,E32*$E$7/12) | AU33: =IF(E32<=0,0,MIN(E32+AT33,$F$7+AS33)) | AV33: =IF(E32<=0,AS33,MAX(0,$F$7+AS33-E32-AT33)) | AW33: =IF(F32<=0,0,F32*$E$8/12) | AX33: =IF(F32<=0,0,MIN(F32+AW33,$F$8+AV33)) | AY33: =IF(F32<=0,AV33,MAX(0,$F$8+AV33-F32-AW33)) | AZ33: =IF(G32<=0,0,G32*$E$9/12) | BA33: =IF(G32<=0,0,MIN(G32+AZ33,$F$9+AY33)) | BB33: =IF(G32<=0,AY33,MAX(0,$F$9+AY33-G32-AZ33)) | BC33: =IF(H32<=0,0,H32*$E$10/12) | BD33: =IF(H32<=0,0,MIN(H32+BC33,$F$10+BB33)) | BE33: =IF(H32<=0,BB33,MAX(0,$F$10+BB33-H32-BC33)) | BF33: =IF(I32<=0,0,I32*$E$11/12) | BG33: =IF(I32<=0,0,MIN(I32+BF33,$F$11+BE33)) | BH33: =IF(I32<=0,BE33,MAX(0,$F$11+BE33-I32-BF33)) | BI33: =IF(J32<=0,0,J32*$E$12/12) | BJ33: =IF(J32<=0,0,MIN(J32+BI33,$F$12+BH33)) | BK33: =IF(J32<=0,BH33,MAX(0,$F$12+BH33-J32-BI33)) | BL33: =IF(K32<=0,0,K32*$E$13/12) | BM33: =IF(K32<=0,0,MIN(K32+BL33,$F$13+BK33)) | BN33: =IF(K32<=0,BK33,MAX(0,$F$13+BK33-K32-BL33)) | BO33: =IF(L32<=0,0,L32*$E$14/12) | BP33: =IF(L32<=0,0,MIN(L32+BO33,$F$14+BN33)) | BQ33: =IF(L32<=0,BN33,MAX(0,$F$14+BN33-L32-BO33)) | BR33: =IF(M32<=0,0,M32*$E$15/12) | BS33: =IF(M32<=0,0,MIN(M32+BR33,$F$15+BQ33)) | BT33: =IF(M32<=0,BQ33,MAX(0,$F$15+BQ33-M32-BR33)) | BU33: =IF(N32<=0,0,N32*$E$16/12) | BV33: =IF(N32<=0,0,MIN(N32+BU33,$F$16+BT33)) | BW33: =IF(N32<=0,BT33,MAX(0,$F$16+BT33-N32-BU33)) | BX33: =IF(O32<=0,0,O32*$E$17/12) | BY33: =IF(O32<=0,0,MIN(O32+BX33,$F$17+BW33)) | BZ33: =IF(O32<=0,BW33,MAX(0,$F$17+BW33-O32-BX33)) | CA33: =IF(P32<=0,0,P32*$E$18/12) | CB33: =IF(P32<=0,0,MIN(P32+CA33,$F$18+BZ33)) | CC33: =IF(P32<=0,BZ33,MAX(0,$F$18+BZ33-P32-CA33)) | CD33: =IF(Q32<=0,0,Q32*$E$19/12) | CE33: =IF(Q32<=0,0,MIN(Q32+CD33,$F$19+CC33)) | CF33: =IF(Q32<=0,CC33,MAX(0,$F$19+CC33-Q32-CD33)) | CG33: =IF(R32<=0,0,R32*$E$20/12) | CH33: =IF(R32<=0,0,MIN(R32+CG33,$F$20+CF33)) | CI33: =IF(R32<=0,CF33,MAX(0,$F$20+CF33-R32-CG33)) | CJ33: =IF(S32<=0,0,S32*$E$21/12) | CK33: =IF(S32<=0,0,MIN(S32+CJ33,$F$21+CI33)) | CL33: =IF(S32<=0,CI33,MAX(0,$F$21+CI33-S32-CJ33)) | CM33: =IF(T32<=0,0,T32*$E$22/12) | CN33: =IF(T32<=0,0,MIN(T32+CM33,$F$22+CL33)) | CO33: =IF(T32<=0,CL33,MAX(0,$F$22+CL33-T32-CM33)) | CP33: =IF(U32<=0,0,U32*$E$23/12) | CQ33: =IF(U32<=0,0,MIN(U32+CP33,$F$23+CO33)) | CR33: =IF(U32<=0,CO33,MAX(0,$F$23+CO33-U32-CP33)) | CS33: =IF(V32<=0,0,V32*$E$24/12) | CT33: =IF(V32<=0,0,MIN(V32+CS33,$F$24+CR33)) | CU33: =IF(V32<=0,CR33,MAX(0,$F$24+CR33-V32-CS33))
B34: 8 | C34: =IF(C33<=0,0,MAX(0,C33+AN34-AO34)) | D34: =IF(D33<=0,0,MAX(0,D33+AQ34-AR34)) | E34: =IF(E33<=0,0,MAX(0,E33+AT34-AU34)) | F34: =IF(F33<=0,0,MAX(0,F33+AW34-AX34)) | G34: =IF(G33<=0,0,MAX(0,G33+AZ34-BA34)) | H34: =IF(H33<=0,0,MAX(0,H33+BC34-BD34)) | I34: =IF(I33<=0,0,MAX(0,I33+BF34-BG34)) | J34: =IF(J33<=0,0,MAX(0,J33+BI34-BJ34)) | K34: =IF(K33<=0,0,MAX(0,K33+BL34-BM34)) | L34: =IF(L33<=0,0,MAX(0,L33+BO34-BP34)) | M34: =IF(M33<=0,0,MAX(0,M33+BR34-BS34)) | N34: =IF(N33<=0,0,MAX(0,N33+BU34-BV34)) | O34: =IF(O33<=0,0,MAX(0,O33+BX34-BY34)) | P34: =IF(P33<=0,0,MAX(0,P33+CA34-CB34)) | Q34: =IF(Q33<=0,0,MAX(0,Q33+CD34-CE34)) | R34: =IF(R33<=0,0,MAX(0,R33+CG34-CH34)) | S34: =IF(S33<=0,0,MAX(0,S33+CJ34-CK34)) | T34: =IF(T33<=0,0,MAX(0,T33+CM34-CN34)) | U34: =IF(U33<=0,0,MAX(0,U33+CP34-CQ34)) | V34: =IF(V33<=0,0,MAX(0,V33+CS34-CT34)) | W34: =AO34+AR34+AU34+AX34+BA34+BD34+BG34+BJ34+BM34+BP34+BS34+BV34+BY34+CB34+CE34+CH34+CK34+CN34+CQ34+CT34 | X34: =AN34+AQ34+AT34+AW34+AZ34+BC34+BF34+BI34+BL34+BO34+BR34+BU34+BX34+CA34+CD34+CG34+CJ34+CM34+CP34+CS34 | Y34: =C34+D34+E34+F34+G34+H34+I34+J34+K34+L34+M34+N34+O34+P34+Q34+R34+S34+T34+U34+V34 | AN34: =IF(C33<=0,0,C33*$E$5/12) | AO34: =IF(C33<=0,0,MIN(C33+AN34,$F$5+(Dashboard!$C$11+IF(C33<=0,$F$5,0)+IF(D33<=0,$F$6,0)+IF(E33<=0,$F$7,0)+IF(F33<=0,$F$8,0)+IF(G33<=0,$F$9,0)+IF(H33<=0,$F$10,0)+IF(I33<=0,$F$11,0)+IF(J33<=0,$F$12,0)+IF(K33<=0,$F$13,0)+IF(L33<=0,$F$14,0)+IF(M33<=0,$F$15,0)+IF(N33<=0,$F$16,0)+IF(O33<=0,$F$17,0)+IF(P33<=0,$F$18,0)+IF(Q33<=0,$F$19,0)+IF(R33<=0,$F$20,0)+IF(S33<=0,$F$21,0)+IF(T33<=0,$F$22,0)+IF(U33<=0,$F$23,0)+IF(V33<=0,$F$24,0)))) | AP34: =IF(C33<=0,(Dashboard!$C$11+IF(C33<=0,$F$5,0)+IF(D33<=0,$F$6,0)+IF(E33<=0,$F$7,0)+IF(F33<=0,$F$8,0)+IF(G33<=0,$F$9,0)+IF(H33<=0,$F$10,0)+IF(I33<=0,$F$11,0)+IF(J33<=0,$F$12,0)+IF(K33<=0,$F$13,0)+IF(L33<=0,$F$14,0)+IF(M33<=0,$F$15,0)+IF(N33<=0,$F$16,0)+IF(O33<=0,$F$17,0)+IF(P33<=0,$F$18,0)+IF(Q33<=0,$F$19,0)+IF(R33<=0,$F$20,0)+IF(S33<=0,$F$21,0)+IF(T33<=0,$F$22,0)+IF(U33<=0,$F$23,0)+IF(V33<=0,$F$24,0)),MAX(0,$F$5+(Dashboard!$C$11+IF(C33<=0,$F$5,0)+IF(D33<=0,$F$6,0)+IF(E33<=0,$F$7,0)+IF(F33<=0,$F$8,0)+IF(G33<=0,$F$9,0)+IF(H33<=0,$F$10,0)+IF(I33<=0,$F$11,0)+IF(J33<=0,$F$12,0)+IF(K33<=0,$F$13,0)+IF(L33<=0,$F$14,0)+IF(M33<=0,$F$15,0)+IF(N33<=0,$F$16,0)+IF(O33<=0,$F$17,0)+IF(P33<=0,$F$18,0)+IF(Q33<=0,$F$19,0)+IF(R33<=0,$F$20,0)+IF(S33<=0,$F$21,0)+IF(T33<=0,$F$22,0)+IF(U33<=0,$F$23,0)+IF(V33<=0,$F$24,0))-C33-AN34)) | AQ34: =IF(D33<=0,0,D33*$E$6/12) | AR34: =IF(D33<=0,0,MIN(D33+AQ34,$F$6+AP34)) | AS34: =IF(D33<=0,AP34,MAX(0,$F$6+AP34-D33-AQ34)) | AT34: =IF(E33<=0,0,E33*$E$7/12) | AU34: =IF(E33<=0,0,MIN(E33+AT34,$F$7+AS34)) | AV34: =IF(E33<=0,AS34,MAX(0,$F$7+AS34-E33-AT34)) | AW34: =IF(F33<=0,0,F33*$E$8/12) | AX34: =IF(F33<=0,0,MIN(F33+AW34,$F$8+AV34)) | AY34: =IF(F33<=0,AV34,MAX(0,$F$8+AV34-F33-AW34)) | AZ34: =IF(G33<=0,0,G33*$E$9/12) | BA34: =IF(G33<=0,0,MIN(G33+AZ34,$F$9+AY34)) | BB34: =IF(G33<=0,AY34,MAX(0,$F$9+AY34-G33-AZ34)) | BC34: =IF(H33<=0,0,H33*$E$10/12) | BD34: =IF(H33<=0,0,MIN(H33+BC34,$F$10+BB34)) | BE34: =IF(H33<=0,BB34,MAX(0,$F$10+BB34-H33-BC34)) | BF34: =IF(I33<=0,0,I33*$E$11/12) | BG34: =IF(I33<=0,0,MIN(I33+BF34,$F$11+BE34)) | BH34: =IF(I33<=0,BE34,MAX(0,$F$11+BE34-I33-BF34)) | BI34: =IF(J33<=0,0,J33*$E$12/12) | BJ34: =IF(J33<=0,0,MIN(J33+BI34,$F$12+BH34)) | BK34: =IF(J33<=0,BH34,MAX(0,$F$12+BH34-J33-BI34)) | BL34: =IF(K33<=0,0,K33*$E$13/12) | BM34: =IF(K33<=0,0,MIN(K33+BL34,$F$13+BK34)) | BN34: =IF(K33<=0,BK34,MAX(0,$F$13+BK34-K33-BL34)) | BO34: =IF(L33<=0,0,L33*$E$14/12) | BP34: =IF(L33<=0,0,MIN(L33+BO34,$F$14+BN34)) | BQ34: =IF(L33<=0,BN34,MAX(0,$F$14+BN34-L33-BO34)) | BR34: =IF(M33<=0,0,M33*$E$15/12) | BS34: =IF(M33<=0,0,MIN(M33+BR34,$F$15+BQ34)) | BT34: =IF(M33<=0,BQ34,MAX(0,$F$15+BQ34-M33-BR34)) | BU34: =IF(N33<=0,0,N33*$E$16/12) | BV34: =IF(N33<=0,0,MIN(N33+BU34,$F$16+BT34)) | BW34: =IF(N33<=0,BT34,MAX(0,$F$16+BT34-N33-BU34)) | BX34: =IF(O33<=0,0,O33*$E$17/12) | BY34: =IF(O33<=0,0,MIN(O33+BX34,$F$17+BW34)) | BZ34: =IF(O33<=0,BW34,MAX(0,$F$17+BW34-O33-BX34)) | CA34: =IF(P33<=0,0,P33*$E$18/12) | CB34: =IF(P33<=0,0,MIN(P33+CA34,$F$18+BZ34)) | CC34: =IF(P33<=0,BZ34,MAX(0,$F$18+BZ34-P33-CA34)) | CD34: =IF(Q33<=0,0,Q33*$E$19/12) | CE34: =IF(Q33<=0,0,MIN(Q33+CD34,$F$19+CC34)) | CF34: =IF(Q33<=0,CC34,MAX(0,$F$19+CC34-Q33-CD34)) | CG34: =IF(R33<=0,0,R33*$E$20/12) | CH34: =IF(R33<=0,0,MIN(R33+CG34,$F$20+CF34)) | CI34: =IF(R33<=0,CF34,MAX(0,$F$20+CF34-R33-CG34)) | CJ34: =IF(S33<=0,0,S33*$E$21/12) | CK34: =IF(S33<=0,0,MIN(S33+CJ34,$F$21+CI34)) | CL34: =IF(S33<=0,CI34,MAX(0,$F$21+CI34-S33-CJ34)) | CM34: =IF(T33<=0,0,T33*$E$22/12) | CN34: =IF(T33<=0,0,MIN(T33+CM34,$F$22+CL34)) | CO34: =IF(T33<=0,CL34,MAX(0,$F$22+CL34-T33-CM34)) | CP34: =IF(U33<=0,0,U33*$E$23/12) | CQ34: =IF(U33<=0,0,MIN(U33+CP34,$F$23+CO34)) | CR34: =IF(U33<=0,CO34,MAX(0,$F$23+CO34-U33-CP34)) | CS34: =IF(V33<=0,0,V33*$E$24/12) | CT34: =IF(V33<=0,0,MIN(V33+CS34,$F$24+CR34)) | CU34: =IF(V33<=0,CR34,MAX(0,$F$24+CR34-V33-CS34))
B35: 9 | C35: =IF(C34<=0,0,MAX(0,C34+AN35-AO35)) | D35: =IF(D34<=0,0,MAX(0,D34+AQ35-AR35)) | E35: =IF(E34<=0,0,MAX(0,E34+AT35-AU35)) | F35: =IF(F34<=0,0,MAX(0,F34+AW35-AX35)) | G35: =IF(G34<=0,0,MAX(0,G34+AZ35-BA35)) | H35: =IF(H34<=0,0,MAX(0,H34+BC35-BD35)) | I35: =IF(I34<=0,0,MAX(0,I34+BF35-BG35)) | J35: =IF(J34<=0,0,MAX(0,J34+BI35-BJ35)) | K35: =IF(K34<=0,0,MAX(0,K34+BL35-BM35)) | L35: =IF(L34<=0,0,MAX(0,L34+BO35-BP35)) | M35: =IF(M34<=0,0,MAX(0,M34+BR35-BS35)) | N35: =IF(N34<=0,0,MAX(0,N34+BU35-BV35)) | O35: =IF(O34<=0,0,MAX(0,O34+BX35-BY35)) | P35: =IF(P34<=0,0,MAX(0,P34+CA35-CB35)) | Q35: =IF(Q34<=0,0,MAX(0,Q34+CD35-CE35)) | R35: =IF(R34<=0,0,MAX(0,R34+CG35-CH35)) | S35: =IF(S34<=0,0,MAX(0,S34+CJ35-CK35)) | T35: =IF(T34<=0,0,MAX(0,T34+CM35-CN35)) | U35: =IF(U34<=0,0,MAX(0,U34+CP35-CQ35)) | V35: =IF(V34<=0,0,MAX(0,V34+CS35-CT35)) | W35: =AO35+AR35+AU35+AX35+BA35+BD35+BG35+BJ35+BM35+BP35+BS35+BV35+BY35+CB35+CE35+CH35+CK35+CN35+CQ35+CT35 | X35: =AN35+AQ35+AT35+AW35+AZ35+BC35+BF35+BI35+BL35+BO35+BR35+BU35+BX35+CA35+CD35+CG35+CJ35+CM35+CP35+CS35 | Y35: =C35+D35+E35+F35+G35+H35+I35+J35+K35+L35+M35+N35+O35+P35+Q35+R35+S35+T35+U35+V35 | AN35: =IF(C34<=0,0,C34*$E$5/12) | AO35: =IF(C34<=0,0,MIN(C34+AN35,$F$5+(Dashboard!$C$11+IF(C34<=0,$F$5,0)+IF(D34<=0,$F$6,0)+IF(E34<=0,$F$7,0)+IF(F34<=0,$F$8,0)+IF(G34<=0,$F$9,0)+IF(H34<=0,$F$10,0)+IF(I34<=0,$F$11,0)+IF(J34<=0,$F$12,0)+IF(K34<=0,$F$13,0)+IF(L34<=0,$F$14,0)+IF(M34<=0,$F$15,0)+IF(N34<=0,$F$16,0)+IF(O34<=0,$F$17,0)+IF(P34<=0,$F$18,0)+IF(Q34<=0,$F$19,0)+IF(R34<=0,$F$20,0)+IF(S34<=0,$F$21,0)+IF(T34<=0,$F$22,0)+IF(U34<=0,$F$23,0)+IF(V34<=0,$F$24,0)))) | AP35: =IF(C34<=0,(Dashboard!$C$11+IF(C34<=0,$F$5,0)+IF(D34<=0,$F$6,0)+IF(E34<=0,$F$7,0)+IF(F34<=0,$F$8,0)+IF(G34<=0,$F$9,0)+IF(H34<=0,$F$10,0)+IF(I34<=0,$F$11,0)+IF(J34<=0,$F$12,0)+IF(K34<=0,$F$13,0)+IF(L34<=0,$F$14,0)+IF(M34<=0,$F$15,0)+IF(N34<=0,$F$16,0)+IF(O34<=0,$F$17,0)+IF(P34<=0,$F$18,0)+IF(Q34<=0,$F$19,0)+IF(R34<=0,$F$20,0)+IF(S34<=0,$F$21,0)+IF(T34<=0,$F$22,0)+IF(U34<=0,$F$23,0)+IF(V34<=0,$F$24,0)),MAX(0,$F$5+(Dashboard!$C$11+IF(C34<=0,$F$5,0)+IF(D34<=0,$F$6,0)+IF(E34<=0,$F$7,0)+IF(F34<=0,$F$8,0)+IF(G34<=0,$F$9,0)+IF(H34<=0,$F$10,0)+IF(I34<=0,$F$11,0)+IF(J34<=0,$F$12,0)+IF(K34<=0,$F$13,0)+IF(L34<=0,$F$14,0)+IF(M34<=0,$F$15,0)+IF(N34<=0,$F$16,0)+IF(O34<=0,$F$17,0)+IF(P34<=0,$F$18,0)+IF(Q34<=0,$F$19,0)+IF(R34<=0,$F$20,0)+IF(S34<=0,$F$21,0)+IF(T34<=0,$F$22,0)+IF(U34<=0,$F$23,0)+IF(V34<=0,$F$24,0))-C34-AN35)) | AQ35: =IF(D34<=0,0,D34*$E$6/12) | AR35: =IF(D34<=0,0,MIN(D34+AQ35,$F$6+AP35)) | AS35: =IF(D34<=0,AP35,MAX(0,$F$6+AP35-D34-AQ35)) | AT35: =IF(E34<=0,0,E34*$E$7/12) | AU35: =IF(E34<=0,0,MIN(E34+AT35,$F$7+AS35)) | AV35: =IF(E34<=0,AS35,MAX(0,$F$7+AS35-E34-AT35)) | AW35: =IF(F34<=0,0,F34*$E$8/12) | AX35: =IF(F34<=0,0,MIN(F34+AW35,$F$8+AV35)) | AY35: =IF(F34<=0,AV35,MAX(0,$F$8+AV35-F34-AW35)) | AZ35: =IF(G34<=0,0,G34*$E$9/12) | BA35: =IF(G34<=0,0,MIN(G34+AZ35,$F$9+AY35)) | BB35: =IF(G34<=0,AY35,MAX(0,$F$9+AY35-G34-AZ35)) | BC35: =IF(H34<=0,0,H34*$E$10/12) | BD35: =IF(H34<=0,0,MIN(H34+BC35,$F$10+BB35)) | BE35: =IF(H34<=0,BB35,MAX(0,$F$10+BB35-H34-BC35)) | BF35: =IF(I34<=0,0,I34*$E$11/12) | BG35: =IF(I34<=0,0,MIN(I34+BF35,$F$11+BE35)) | BH35: =IF(I34<=0,BE35,MAX(0,$F$11+BE35-I34-BF35)) | BI35: =IF(J34<=0,0,J34*$E$12/12) | BJ35: =IF(J34<=0,0,MIN(J34+BI35,$F$12+BH35)) | BK35: =IF(J34<=0,BH35,MAX(0,$F$12+BH35-J34-BI35)) | BL35: =IF(K34<=0,0,K34*$E$13/12) | BM35: =IF(K34<=0,0,MIN(K34+BL35,$F$13+BK35)) | BN35: =IF(K34<=0,BK35,MAX(0,$F$13+BK35-K34-BL35)) | BO35: =IF(L34<=0,0,L34*$E$14/12) | BP35: =IF(L34<=0,0,MIN(L34+BO35,$F$14+BN35)) | BQ35: =IF(L34<=0,BN35,MAX(0,$F$14+BN35-L34-BO35)) | BR35: =IF(M34<=0,0,M34*$E$15/12) | BS35: =IF(M34<=0,0,MIN(M34+BR35,$F$15+BQ35)) | BT35: =IF(M34<=0,BQ35,MAX(0,$F$15+BQ35-M34-BR35)) | BU35: =IF(N34<=0,0,N34*$E$16/12) | BV35: =IF(N34<=0,0,MIN(N34+BU35,$F$16+BT35)) | BW35: =IF(N34<=0,BT35,MAX(0,$F$16+BT35-N34-BU35)) | BX35: =IF(O34<=0,0,O34*$E$17/12) | BY35: =IF(O34<=0,0,MIN(O34+BX35,$F$17+BW35)) | BZ35: =IF(O34<=0,BW35,MAX(0,$F$17+BW35-O34-BX35)) | CA35: =IF(P34<=0,0,P34*$E$18/12) | CB35: =IF(P34<=0,0,MIN(P34+CA35,$F$18+BZ35)) | CC35: =IF(P34<=0,BZ35,MAX(0,$F$18+BZ35-P34-CA35)) | CD35: =IF(Q34<=0,0,Q34*$E$19/12) | CE35: =IF(Q34<=0,0,MIN(Q34+CD35,$F$19+CC35)) | CF35: =IF(Q34<=0,CC35,MAX(0,$F$19+CC35-Q34-CD35)) | CG35: =IF(R34<=0,0,R34*$E$20/12) | CH35: =IF(R34<=0,0,MIN(R34+CG35,$F$20+CF35)) | CI35: =IF(R34<=0,CF35,MAX(0,$F$20+CF35-R34-CG35)) | CJ35: =IF(S34<=0,0,S34*$E$21/12) | CK35: =IF(S34<=0,0,MIN(S34+CJ35,$F$21+CI35)) | CL35: =IF(S34<=0,CI35,MAX(0,$F$21+CI35-S34-CJ35)) | CM35: =IF(T34<=0,0,T34*$E$22/12) | CN35: =IF(T34<=0,0,MIN(T34+CM35,$F$22+CL35)) | CO35: =IF(T34<=0,CL35,MAX(0,$F$22+CL35-T34-CM35)) | CP35: =IF(U34<=0,0,U34*$E$23/12) | CQ35: =IF(U34<=0,0,MIN(U34+CP35,$F$23+CO35)) | CR35: =IF(U34<=0,CO35,MAX(0,$F$23+CO35-U34-CP35)) | CS35: =IF(V34<=0,0,V34*$E$24/12) | CT35: =IF(V34<=0,0,MIN(V34+CS35,$F$24+CR35)) | CU35: =IF(V34<=0,CR35,MAX(0,$F$24+CR35-V34-CS35))
