Workbook

Sheet Instructions
A1: SUBSCRIPTION TRACKER
A2: Take control of your recurring expenses. Find hidden costs. Save hundreds per year.
A4: WELCOME
A5: Thank you for purchasing this Subscription Tracker! This workbook helps you catalog every
A6: recurring charge, visualize where your money goes, and identify subscriptions to cut.
A7: The average person has 12 active subscriptions and wastes $30-100/month on forgotten ones.
A9: HOW TO USE EACH SHEET
A10: 1. ALL SUBSCRIPTIONS -- Enter every subscription you have. Dropdowns help you fill in
A11: categories, billing cycles, and status. Formulas auto-calculate annual costs.
A13: 2. DASHBOARD -- See totals, averages, and category breakdowns update automatically.
A14: No editing needed here; everything pulls from your subscription list.
A16: 3. RENEWAL CALENDAR -- View which subscriptions renew each month so you can plan ahead
... A51: 10. The $5 rule: Small charges add up. Five $5 subscriptions = $300/year.

Sheet Dashboard
A1: SUBSCRIPTION DASHBOARD
A2: All figures update automatically from the All Subscriptions sheet.
B4: KEY METRICS | E4: QUICK STATS
B5: Total Monthly Cost | C5: =IFERROR(SUMPRODUCT(('All Subscriptions'!I4:I103<>"Canceled")*'All Subscriptions'!C4:C103),0) | E5: Active Subscriptions | F5: =COUNTIF('All Subscriptions'!I4:I103,"Active")
B6: Total Annual Cost | C6: =IFERROR(SUMPRODUCT(('All Subscriptions'!I4:I103<>"Canceled")*'All Subscriptions'!D4:D103),0) | E6: Paused Subscriptions | F6: =COUNTIF('All Subscriptions'!I4:I103,"Paused")
B7: Average Monthly Cost | C7: =IFERROR(SUMPRODUCT(('All Subscriptions'!I4:I103="Active")*'All Subscriptions'!C4:C103)/COUNTIF('All Subscriptions'!I4:I103,"Active"),0) | E7: Consider Canceling | F7: =COUNTIF('All Subscriptions'!I4:I103,"Consider Canceling")
B8: Most Expensive (Monthly) | C8: =IFERROR(MAX(IF('All Subscriptions'!I4:I103<>"Canceled",'All Subscriptions'!C4:C103)),0) | E8: Canceled Subscriptions | F8: =COUNTIF('All Subscriptions'!I4:I103,"Canceled")
B10: CATEGORY BREAKDOWN
B11: Category | C11: Count | E11: Monthly Total | F11: Annual Total
B12: Entertainment | C12: =COUNTIFS('All Subscriptions'!B4:B103,"Entertainment",'All Subscriptions'!I4:I103,"<>Canceled") | E12: =IFERROR(SUMPRODUCT(('All Subscriptions'!B4:B103="Entertainment")*('All Subscriptions'!I4:I103<>"Canceled")*'All Subscriptions'!C4:C103),0) | F12: =IFERROR(SUMPRODUCT(('All Subscriptions'!B4:B103="Entertainment")*('All Subscriptions'!I4:I103<>"Canceled")*'All Subscriptions'!D4:D103),0)
B13: Software | C13: =COUNTIFS('All Subscriptions'!B4:B103,"Software",'All Subscriptions'!I4:I103,"<>Canceled") | E13: =IFERROR(SUMPRODUCT(('All Subscriptions'!B4:B103="Software")*('All Subscriptions'!I4:I103<>"Canceled")*'All Subscriptions'!C4:C103),0) | F13: =IFERROR(SUMPRODUCT(('All Subscriptions'!B4:B103="Software")*('All Subscriptions'!I4:I103<>"Canceled")*'All Subscriptions'!D4:D103),0)
B14: Health & Fitness | C14: =COUNTIFS('All Subscriptions'!B4:B103,"Health & Fitness",'All Subscriptions'!I4:I103,"<>Canceled") | E14: =IFERROR(SUMPRODUCT(('All Subscriptions'!B4:B103="Health & Fitness")*('All Subscriptions'!I4:I103<>"Canceled")*'All Subscriptions'!C4:C103),0) | F14: =IFERROR(SUMPRODUCT(('All Subscriptions'!B4:B103="Health & Fitness")*('All Subscriptions'!I4:I103<>"Canceled")*'All Subscriptions'!D4:D103),0)
B15: News & Media | C15: =COUNTIFS('All Subscriptions'!B4:B103,"News & Media",'All Subscriptions'!I4:I103,"<>Canceled") | E15: =IFERROR(SUMPRODUCT(('All Subscriptions'!B4:B103="News & Media")*('All Subscriptions'!I4:I103<>"Canceled")*'All Subscriptions'!C4:C103),0) | F15: =IFERROR(SUMPRODUCT(('All Subscriptions'!B4:B103="News & Media")*('All Subscriptions'!I4:I103<>"Canceled")*'All Subscriptions'!D4:D103),0)
B16: Food & Delivery | C16: =COUNTIFS('All Subscriptions'!B4:B103,"Food & Delivery",'All Subscriptions'!I4:I103,"<>Canceled") | E16: =IFERROR(SUMPRODUCT(('All Subscriptions'!B4:B103="Food & Delivery")*('All Subscriptions'!I4:I103<>"Canceled")*'All Subscriptions'!C4:C103),0) | F16: =IFERROR(SUMPRODUCT(('All Subscriptions'!B4:B103="Food & Delivery")*('All Subscriptions'!I4:I103<>"Canceled")*'All Subscriptions'!D4:D103),0)
B17: Cloud Storage | C17: =COUNTIFS('All Subscriptions'!B4:B103,"Cloud Storage",'All Subscriptions'!I4:I103,"<>Canceled") | E17: =IFERROR(SUMPRODUCT(('All Subscriptions'!B4:B103="Cloud Storage")*('All Subscriptions'!I4:I103<>"Canceled")*'All Subscriptions'!C4:C103),0) | F17: =IFERROR(SUMPRODUCT(('All Subscriptions'!B4:B103="Cloud Storage")*('All Subscriptions'!I4:I103<>"Canceled")*'All Subscriptions'!D4:D103),0)
B18: Music | C18: =COUNTIFS('All Subscriptions'!B4:B103,"Music",'All Subscriptions'!I4:I103,"<>Canceled") | E18: =IFERROR(SUMPRODUCT(('All Subscriptions'!B4:B103="Music")*('All Subscriptions'!I4:I103<>"Canceled")*'All Subscriptions'!C4:C103),0) | F18: =IFERROR(SUMPRODUCT(('All Subscriptions'!B4:B103="Music")*('All Subscriptions'!I4:I103<>"Canceled")*'All Subscriptions'!D4:D103),0)
B19: Gaming | C19: =IFERROR(COUNTIFS('All Subscriptions'!B4:B103,"Gaming",'All Subscriptions'!I4:I103,"<>Canceled"),0) | E19: =IFERROR(SUMPRODUCT(('All Subscriptions'!B4:B103="Gaming")*('All Subscriptions'!I4:I103<>"Canceled")*'All Subscriptions'!C4:C103),0) | F19: =IFERROR(SUMPRODUCT(('All Subscriptions'!B4:B103="Gaming")*('All Subscriptions'!I4:I103<>"Canceled")*'All Subscriptions'!D4:D103),0)
B20: Productivity | C20: =COUNTIFS('All Subscriptions'!B4:B103,"Productivity",'All Subscriptions'!I4:I103,"<>Canceled") | E20: =IFERROR(SUMPRODUCT(('All Subscriptions'!B4:B103="Productivity")*('All Subscriptions'!I4:I103<>"Canceled")*'All Subscriptions'!C4:C103),0) | F20: =IFERROR(SUMPRODUCT(('All Subscriptions'!B4:B103="Productivity")*('All Subscriptions'!I4:I103<>"Canceled")*'All Subscriptions'!D4:D103),0)
B21: Other | C21: =COUNTIFS('All Subscriptions'!B4:B103,"Other",'All Subscriptions'!I4:I103,"<>Canceled") | E21: =IFERROR(SUMPRODUCT(('All Subscriptions'!B4:B103="Other")*('All Subscriptions'!I4:I103<>"Canceled")*'All Subscriptions'!C4:C103),0) | F21: =IFERROR(SUMPRODUCT(('All Subscriptions'!B4:B103="Other")*('All Subscriptions'!I4:I103<>"Canceled")*'All Subscriptions'!D4:D103),0)
B22: TOTAL | C22: =SUM(C12:C21) | E22: =SUM(E12:E21) | F22: =SUM(F12:F21)
B24: POTENTIAL SAVINGS -- Subscriptions Marked "Consider Canceling"
B25: Service Name | C25: Category | E25: Monthly Cost | F25: Annual Cost
B26: =IF(COUNTIF('All Subscriptions'!I4:I103,"Consider Canceling")>=1,IFERROR(INDEX('All Subscriptions'!A4:A103,SMALL(IF('All Subscriptions'!I4:I103="Consider Canceling",ROW('All Subscriptions'!I4:I103)-3),1)),""),"") | C26: =IF(COUNTIF('All Subscriptions'!I4:I103,"Consider Canceling")>=1,IFERROR(INDEX('All Subscriptions'!B4:B103,SMALL(IF('All Subscriptions'!I4:I103="Consider Canceling",ROW('All Subscriptions'!I4:I103)-3),1)),""),"") | E26: =IF(COUNTIF('All Subscriptions'!I4:I103,"Consider Canceling")>=1,IFERROR(INDEX('All Subscriptions'!C4:C103,SMALL(IF('All Subscriptions'!I4:I103="Consider Canceling",ROW('All Subscriptions'!I4:I103)-3),1)),""),"") | F26: =IF(COUNTIF('All Subscriptions'!I4:I103,"Consider Canceling")>=1,IFERROR(INDEX('All Subscriptions'!D4:D103,SMALL(IF('All Subscriptions'!I4:I103="Consider Canceling",ROW('All Subscriptions'!I4:I103)-3),1)),""),"")
B27: =IF(COUNTIF('All Subscriptions'!I4:I103,"Consider Canceling")>=2,IFERROR(INDEX('All Subscriptions'!A4:A103,SMALL(IF('All Subscriptions'!I4:I103="Consider Canceling",ROW('All Subscriptions'!I4:I103)-3),2)),""),"") | C27: =IF(COUNTIF('All Subscriptions'!I4:I103,"Consider Canceling")>=2,IFERROR(INDEX('All Subscriptions'!B4:B103,SMALL(IF('All Subscriptions'!I4:I103="Consider Canceling",ROW('All Subscriptions'!I4:I103)-3),2)),""),"") | E27: =IF(COUNTIF('All Subscriptions'!I4:I103,"Consider Canceling")>=2,IFERROR(INDEX('All Subscriptions'!C4:C103,SMALL(IF('All Subscriptions'!I4:I103="Consider Canceling",ROW('All Subscriptions'!I4:I103)-3),2)),""),"") | F27: =IF(COUNTIF('All Subscriptions'!I4:I103,"Consider Canceling")>=2,IFERROR(INDEX('All Subscriptions'!D4:D103,SMALL(IF('All Subscriptions'!I4:I103="Consider Canceling",ROW('All Subscriptions'!I4:I103)-3),2)),""),"")
B28: =IF(COUNTIF('All Subscriptions'!I4:I103,"Consider Canceling")>=3,IFERROR(INDEX('All Subscriptions'!A4:A103,SMALL(IF('All Subscriptions'!I4:I103="Consider Canceling",ROW('All Subscriptions'!I4:I103)-3),3)),""),"") | C28: =IF(COUNTIF('All Subscriptions'!I4:I103,"Consider Canceling")>=3,IFERROR(INDEX('All Subscriptions'!B4:B103,SMALL(IF('All Subscriptions'!I4:I103="Consider Canceling",ROW('All Subscriptions'!I4:I103)-3),3)),""),"") | E28: =IF(COUNTIF('All Subscriptions'!I4:I103,"Consider Canceling")>=3,IFERROR(INDEX('All Subscriptions'!C4:C103,SMALL(IF('All Subscriptions'!I4:I103="Consider Canceling",ROW('All Subscriptions'!I4:I103)-3),3)),""),"") | F28: =IF(COUNTIF('All Subscriptions'!I4:I103,"Consider Canceling")>=3,IFERROR(INDEX('All Subscriptions'!D4:D103,SMALL(IF('All Subscriptions'!I4:I103="Consider Canceling",ROW('All Subscriptions'!I4:I103)-3),3)),""),"")
B29: =IF(COUNTIF('All Subscriptions'!I4:I103,"Consider Canceling")>=4,IFERROR(INDEX('All Subscriptions'!A4:A103,SMALL(IF('All Subscriptions'!I4:I103="Consider Canceling",ROW('All Subscriptions'!I4:I103)-3),4)),""),"") | C29: =IF(COUNTIF('All Subscriptions'!I4:I103,"Consider Canceling")>=4,IFERROR(INDEX('All Subscriptions'!B4:B103,SMALL(IF('All Subscriptions'!I4:I103="Consider Canceling",ROW('All Subscriptions'!I4:I103)-3),4)),""),"") | E29: =IF(COUNTIF('All Subscriptions'!I4:I103,"Consider Canceling")>=4,IFERROR(INDEX('All Subscriptions'!C4:C103,SMALL(IF('All Subscriptions'!I4:I103="Consider Canceling",ROW('All Subscriptions'!I4:I103)-3),4)),""),"") | F29: =IF(COUNTIF('All Subscriptions'!I4:I103,"Consider Canceling")>=4,IFERROR(INDEX('All Subscriptions'!D4:D103,SMALL(IF('All Subscriptions'!I4:I103="Consider Canceling",ROW('All Subscriptions'!I4:I103)-3),4)),""),"")
B30: =IF(COUNTIF('All Subscriptions'!I4:I103,"Consider Canceling")>=5,IFERROR(INDEX('All Subscriptions'!A4:A103,SMALL(IF('All Subscriptions'!I4:I103="Consider Canceling",ROW('All Subscriptions'!I4:I103)-3),5)),""),"") | C30: =IF(COUNTIF('All Subscriptions'!I4:I103,"Consider Canceling")>=5,IFERROR(INDEX('All Subscriptions'!B4:B103,SMALL(IF('All Subscriptions'!I4:I103="Consider Canceling",ROW('All Subscriptions'!I4:I103)-3),5)),""),"") | E30: =IF(COUNTIF('All Subscriptions'!I4:I103,"Consider Canceling")>=5,IFERROR(INDEX('All Subscriptions'!C4:C103,SMALL(IF('All Subscriptions'!I4:I103="Consider Canceling",ROW('All Subscriptions'!I4:I103)-3),5)),""),"") | F30: =IF(COUNTIF('All Subscriptions'!I4:I103,"Consider Canceling")>=5,IFERROR(INDEX('All Subscriptions'!D4:D103,SMALL(IF('All Subscriptions'!I4:I103="Consider Canceling",ROW('All Subscriptions'!I4:I103)-3),5)),""),"")
B31: =IF(COUNTIF('All Subscriptions'!I4:I103,"Consider Canceling")>=6,IFERROR(INDEX('All Subscriptions'!A4:A103,SMALL(IF('All Subscriptions'!I4:I103="Consider Canceling",ROW('All Subscriptions'!I4:I103)-3),6)),""),"") | C31: =IF(COUNTIF('All Subscriptions'!I4:I103,"Consider Canceling")>=6,IFERROR(INDEX('All Subscriptions'!B4:B103,SMALL(IF('All Subscriptions'!I4:I103="Consider Canceling",ROW('All Subscriptions'!I4:I103)-3),6)),""),"") | E31: =IF(COUNTIF('All Subscriptions'!I4:I103,"Consider Canceling")>=6,IFERROR(INDEX('All Subscriptions'!C4:C103,SMALL(IF('All Subscriptions'!I4:I103="Consider Canceling",ROW('All Subscriptions'!I4:I103)-3),6)),""),"") | F31: =IF(COUNTIF('All Subscriptions'!I4:I103,"Consider Canceling")>=6,IFERROR(INDEX('All Subscriptions'!D4:D103,SMALL(IF('All Subscriptions'!I4:I103="Consider Canceling",ROW('All Subscriptions'!I4:I103)-3),6)),""),"")
B32: =IF(COUNTIF('All Subscriptions'!I4:I103,"Consider Canceling")>=7,IFERROR(INDEX('All Subscriptions'!A4:A103,SMALL(IF('All Subscriptions'!I4:I103="Consider Canceling",ROW('All Subscriptions'!I4:I103)-3),7)),""),"") | C32: =IF(COUNTIF('All Subscriptions'!I4:I103,"Consider Canceling")>=7,IFERROR(INDEX('All Subscriptions'!B4:B103,SMALL(IF('All Subscriptions'!I4:I103="Consider Canceling",ROW('All Subscriptions'!I4:I103)-3),7)),""),"") | E32: =IF(COUNTIF('All Subscriptions'!I4:I103,"Consider Canceling")>=7,IFERROR(INDEX('All Subscriptions'!C4:C103,SMALL(IF('All Subscriptions'!I4:I103="Consider Canceling",ROW('All Subscriptions'!I4:I103)-3),7)),""),"") | F32: =IF(COUNTIF('All Subscriptions'!I4:I103,"Consider Canceling")>=7,IFERROR(INDEX('All Subscriptions'!D4:D103,SMALL(IF('All Subscriptions'!I4:I103="Consider Canceling",ROW('All Subscriptions'!I4:I103)-3),7)),""),"")
B33: =IF(COUNTIF('All Subscriptions'!I4:I103,"Consider Canceling")>=8,IFERROR(INDEX('All Subscriptions'!A4:A103,SMALL(IF('All Subscriptions'!I4:I103="Consider Canceling",ROW('All Subscriptions'!I4:I103)-3),8)),""),"") | C33: =IF(COUNTIF('All Subscriptions'!I4:I103,"Consider Canceling")>=8,IFERROR(INDEX('All Subscriptions'!B4:B103,SMALL(IF('All Subscriptions'!I4:I103="Consider Canceling",ROW('All Subscriptions'!I4:I103)-3),8)),""),"") | E33: =IF(COUNTIF('All Subscriptions'!I4:I103,"Consider Canceling")>=8,IFERROR(INDEX('All Subscriptions'!C4:C103,SMALL(IF('All Subscriptions'!I4:I103="Consider Canceling",ROW('All Subscriptions'!I4:I103)-3),8)),""),"") | F33: =IF(COUNTIF('All Subscriptions'!I4:I103,"Consider Canceling")>=8,IFERROR(INDEX('All Subscriptions'!D4:D103,SMALL(IF('All Subscriptions'!I4:I103="Consider Canceling",ROW('All Subscriptions'!I4:I103)-3),8)),""),"")
B34: =IF(COUNTIF('All Subscriptions'!I4:I103,"Consider Canceling")>=9,IFERROR(INDEX('All Subscriptions'!A4:A103,SMALL(IF('All Subscriptions'!I4:I103="Consider Canceling",ROW('All Subscriptions'!I4:I103)-3),9)),""),"") | C34: =IF(COUNTIF('All Subscriptions'!I4:I103,"Consider Canceling")>=9,IFERROR(INDEX('All Subscriptions'!B4:B103,SMALL(IF('All Subscriptions'!I4:I103="Consider Canceling",ROW('All Subscriptions'!I4:I103)-3),9)),""),"") | E34: =IF(COUNTIF('All Subscriptions'!I4:I103,"Consider Canceling")>=9,IFERROR(INDEX('All Subscriptions'!C4:C103,SMALL(IF('All Subscriptions'!I4:I103="Consider Canceling",ROW('All Subscriptions'!I4:I103)-3),9)),""),"") | F34: =IF(COUNTIF('All Subscriptions'!I4:I103,"Consider Canceling")>=9,IFERROR(INDEX('All Subscriptions'!D4:D103,SMALL(IF('All Subscriptions'!I4:I103="Consider Canceling",ROW('All Subscriptions'!I4:I103)-3),9)),""),"")
B35: =IF(COUNTIF('All Subscriptions'!I4:I103,"Consider Canceling")>=10,IFERROR(INDEX('All Subscriptions'!A4:A103,SMALL(IF('All Subscriptions'!I4:I103="Consider Canceling",ROW('All Subscriptions'!I4:I103)-3),10)),""),"") | C35: =IF(COUNTIF('All Subscriptions'!I4:I103,"Consider Canceling")>=10,IFERROR(INDEX('All Subscriptions'!B4:B103,SMALL(IF('All Subscriptions'!I4:I103="Consider Canceling",ROW('All Subscriptions'!I4:I103)-3),10)),""),"") | E35: =IF(COUNTIF('All Subscriptions'!I4:I103,"Consider Canceling")>=10,IFERROR(INDEX('All Subscriptions'!C4:C103,SMALL(IF('All Subscriptions'!I4:I103="Consider Canceling",ROW('All Subscriptions'!I4:I103)-3),10)),""),"") | F35: =IF(COUNTIF('All Subscriptions'!I4:I103,"Consider Canceling")>=10,IFERROR(INDEX('All Subscriptions'!D4:D103,SMALL(IF('All Subscriptions'!I4:I103="Consider Canceling",ROW('All Subscriptions'!I4:I103)-3),10)),""),"")
B36: =IF(COUNTIF('All Subscriptions'!I4:I103,"Consider Canceling")>=11,IFERROR(INDEX('All Subscriptions'!A4:A103,SMALL(IF('All Subscriptions'!I4:I103="Consider Canceling",ROW('All Subscriptions'!I4:I103)-3),11)),""),"") | C36: =IF(COUNTIF('All Subscriptions'!I4:I103,"Consider Canceling")>=11,IFERROR(INDEX('All Subscriptions'!B4:B103,SMALL(IF('All Subscriptions'!I4:I103="Consider Canceling",ROW('All Subscriptions'!I4:I103)-3),11)),""),"") | E36: =IF(COUNTIF('All Subscriptions'!I4:I103,"Consider Canceling")>=11,IFERROR(INDEX('All Subscriptions'!C4:C103,SMALL(IF('All Subscriptions'!I4:I103="Consider Canceling",ROW('All Subscriptions'!I4:I103)-3),11)),""),"") | F36: =IF(COUNTIF('All Subscriptions'!I4:I103,"Consider Canceling")>=11,IFERROR(INDEX('All Subscriptions'!D4:D103,SMALL(IF('All Subscriptions'!I4:I103="Consider Canceling",ROW('All Subscriptions'!I4:I103)-3),11)),""),"")
B37: =IF(COUNTIF('All Subscriptions'!I4:I103,"Consider Canceling")>=12,IFERROR(INDEX('All Subscriptions'!A4:A103,SMALL(IF('All Subscriptions'!I4:I103="Consider Canceling",ROW('All Subscriptions'!I4:I103)-3),12)),""),"") | C37: =IF(COUNTIF('All Subscriptions'!I4:I103,"Consider Canceling")>=12,IFERROR(INDEX('All Subscriptions'!B4:B103,SMALL(IF('All Subscriptions'!I4:I103="Consider Canceling",ROW('All Subscriptions'!I4:I103)-3),12)),""),"") | E37: =IF(COUNTIF('All Subscriptions'!I4:I103,"Consider Canceling")>=12,IFERROR(INDEX('All Subscriptions'!C4:C103,SMALL(IF('All Subscriptions'!I4:I103="Consider Canceling",ROW('All Subscriptions'!I4:I103)-3),12)),""),"") | F37: =IF(COUNTIF('All Subscriptions'!I4:I103,"Consider Canceling")>=12,IFERROR(INDEX('All Subscriptions'!D4:D103,SMALL(IF('All Subscriptions'!I4:I103="Consider Canceling",ROW('All Subscriptions'!I4:I103)-3),12)),""),"")
B38: =IF(COUNTIF('All Subscriptions'!I4:I103,"Consider Canceling")>=13,IFERROR(INDEX('All Subscriptions'!A4:A103,SMALL(IF('All Subscriptions'!I4:I103="Consider Canceling",ROW('All Subscriptions'!I4:I103)-3),13)),""),"") | C38: =IF(COUNTIF('All Subscriptions'!I4:I103,"Consider Canceling")>=13,IFERROR(INDEX('All Subscriptions'!B4:B103,SMALL(IF('All Subscriptions'!I4:I103="Consider Canceling",ROW('All Subscriptions'!I4:I103)-3),13)),""),"") | E38: =IF(COUNTIF('All Subscriptions'!I4:I103,"Consider Canceling")>=13,IFERROR(INDEX('All Subscriptions'!C4:C103,SMALL(IF('All Subscriptions'!I4:I103="Consider Canceling",ROW('All Subscriptions'!I4:I103)-3),13)),""),"") | F38: =IF(COUNTIF('All Subscriptions'!I4:I103,"Consider Canceling")>=13,IFERROR(INDEX('All Subscriptions'!D4:D103,SMALL(IF('All Subscriptions'!I4:I103="Consider Canceling",ROW('All Subscriptions'!I4:I103)-3),13)),""),"")
B39: =IF(COUNTIF('All Subscriptions'!I4:I103,"Consider Canceling")>=14,IFERROR(INDEX('All Subscriptions'!A4:A103,SMALL(IF('All Subscriptions'!I4:I103="Consider Canceling",ROW('All Subscriptions'!I4:I103)-3),14)),""),"") | C39: =IF(COUNTIF('All Subscriptions'!I4:I103,"Consider Canceling")>=14,IFERROR(INDEX('All Subscriptions'!B4:B103,SMALL(IF('All Subscriptions'!I4:I103="Consider Canceling",ROW('All Subscriptions'!I4:I103)-3),14)),""),"") | E39: =IF(COUNTIF('All Subscriptions'!I4:I103,"Consider Canceling")>=14,IFERROR(INDEX('All Subscriptions'!C4:C103,SMALL(IF('All Subscriptions'!I4:I103="Consider Canceling",ROW('All Subscriptions'!I4:I103)-3),14)),""),"") | F39: =IF(COUNTIF('All Subscriptions'!I4:I103,"Consider Canceling")>=14,IFERROR(INDEX('All Subscriptions'!D4:D103,SMALL(IF('All Subscriptions'!I4:I103="Consider Canceling",ROW('All Subscriptions'!I4:I103)-3),14)),""),"")
B40: =IF(COUNTIF('All Subscriptions'!I4:I103,"Consider Canceling")>=15,IFERROR(INDEX('All Subscriptions'!A4:A103,SMALL(IF('All Subscriptions'!I4:I103="Consider Canceling",ROW('All Subscriptions'!I4:I103)-3),15)),""),"") | C40: =IF(COUNTIF('All Subscriptions'!I4:I103,"Consider Canceling")>=15,IFERROR(INDEX('All Subscriptions'!B4:B103,SMALL(IF('All Subscriptions'!I4:I103="Consider Canceling",ROW('All Subscriptions'!I4:I103)-3),15)),""),"") | E40: =IF(COUNTIF('All Subscriptions'!I4:I103,"Consider Canceling")>=15,IFERROR(INDEX('All Subscriptions'!C4:C103,SMALL(IF('All Subscriptions'!I4:I103="Consider Canceling",ROW('All Subscriptions'!I4:I103)-3),15)),""),"") | F40: =IF(COUNTIF('All Subscriptions'!I4:I103,"Consider Canceling")>=15,IFERROR(INDEX('All Subscriptions'!D4:D103,SMALL(IF('All Subscriptions'!I4:I103="Consider Canceling",ROW('All Subscriptions'!I4:I103)-3),15)),""),"")
B42: TOTAL POTENTIAL SAVINGS | E42: =IF(COUNTIF('All Subscriptions'!I4:I103,"Consider Canceling")=0,"",IFERROR(SUMPRODUCT(('All Subscriptions'!I4:I103="Consider Canceling")*'All Subscriptions'!C4:C103),0)) | F42: =IF(COUNTIF('All Subscriptions'!I4:I103,"Consider Canceling")=0,"",IFERROR(SUMPRODUCT(('All Subscriptions'!I4:I103="Consider Canceling")*'All Subscriptions'!D4:D103),0))

Sheet All Subscriptions
A1: ALL SUBSCRIPTIONS
A2: Enter all your subscriptions below. Use the dropdowns for categories, billing cycles, and status.
A3: Service Name | B3: Category | C3: Monthly Cost | D3: Annual Cost | E3: Billing Cycle | F3: Next Renewal Date | G3: Auto-Renew | H3: Payment Method | I3: Status | J3: Notes
D4: =IF(C4="",0,C4*12)
D5: =IF(C5="",0,C5*12)
D6: =IF(C6="",0,C6*12)
D7: =IF(C7="",0,C7*12)
D8: =IF(C8="",0,C8*12)
D9: =IF(C9="",0,C9*12)
D10: =IF(C10="",0,C10*12)
D11: =IF(C11="",0,C11*12)
D12: =IF(C12="",0,C12*12)
D13: =IF(C13="",0,C13*12)
D14: =IF(C14="",0,C14*12)
D15: =IF(C15="",0,C15*12)
... D103: =IF(C103="",0,C103*12)

Sheet Renewal Calendar
A1: RENEWAL CALENDAR
A2: See when your subscriptions renew each month. Formulas pull from the All Subscriptions sheet.
B4: JANUARY
B5: Service | C5: Category | D5: Renewal Date | E5: Amount
B6: =IFERROR(INDEX('All Subscriptions'!A4:A103,SMALL(IF(MONTH('All Subscriptions'!F4:F103)=1,ROW('All Subscriptions'!F4:F103)-3),1)),"") | C6: =IFERROR(INDEX('All Subscriptions'!B4:B103,SMALL(IF(MONTH('All Subscriptions'!F4:F103)=1,ROW('All Subscriptions'!F4:F103)-3),1)),"") | D6: =IFERROR(INDEX('All Subscriptions'!F4:F103,SMALL(IF(MONTH('All Subscriptions'!F4:F103)=1,ROW('All Subscriptions'!F4:F103)-3),1)),"") | E6: =IFERROR(INDEX('All Subscriptions'!C4:C103,SMALL(IF(MONTH('All Subscriptions'!F4:F103)=1,ROW('All Subscriptions'!F4:F103)-3),1)),"")
B7: =IFERROR(INDEX('All Subscriptions'!A4:A103,SMALL(IF(MONTH('All Subscriptions'!F4:F103)=1,ROW('All Subscriptions'!F4:F103)-3),2)),"") | C7: =IFERROR(INDEX('All Subscriptions'!B4:B103,SMALL(IF(MONTH('All Subscriptions'!F4:F103)=1,ROW('All Subscriptions'!F4:F103)-3),2)),"") | D7: =IFERROR(INDEX('All Subscriptions'!F4:F103,SMALL(IF(MONTH('All Subscriptions'!F4:F103)=1,ROW('All Subscriptions'!F4:F103)-3),2)),"") | E7: =IFERROR(INDEX('All Subscriptions'!C4:C103,SMALL(IF(MONTH('All Subscriptions'!F4:F103)=1,ROW('All Subscriptions'!F4:F103)-3),2)),"")
B8: =IFERROR(INDEX('All Subscriptions'!A4:A103,SMALL(IF(MONTH('All Subscriptions'!F4:F103)=1,ROW('All Subscriptions'!F4:F103)-3),3)),"") | C8: =IFERROR(INDEX('All Subscriptions'!B4:B103,SMALL(IF(MONTH('All Subscriptions'!F4:F103)=1,ROW('All Subscriptions'!F4:F103)-3),3)),"") | D8: =IFERROR(INDEX('All Subscriptions'!F4:F103,SMALL(IF(MONTH('All Subscriptions'!F4:F103)=1,ROW('All Subscriptions'!F4:F103)-3),3)),"") | E8: =IFERROR(INDEX('All Subscriptions'!C4:C103,SMALL(IF(MONTH('All Subscriptions'!F4:F103)=1,ROW('All Subscriptions'!F4:F103)-3),3)),"")
B9: =IFERROR(INDEX('All Subscriptions'!A4:A103,SMALL(IF(MONTH('All Subscriptions'!F4:F103)=1,ROW('All Subscriptions'!F4:F103)-3),4)),"") | C9: =IFERROR(INDEX('All Subscriptions'!B4:B103,SMALL(IF(MONTH('All Subscriptions'!F4:F103)=1,ROW('All Subscriptions'!F4:F103)-3),4)),"") | D9: =IFERROR(INDEX('All Subscriptions'!F4:F103,SMALL(IF(MONTH('All Subscriptions'!F4:F103)=1,ROW('All Subscriptions'!F4:F103)-3),4)),"") | E9: =IFERROR(INDEX('All Subscriptions'!C4:C103,SMALL(IF(MONTH('All Subscriptions'!F4:F103)=1,ROW('All Subscriptions'!F4:F103)-3),4)),"")
B10: =IFERROR(INDEX('All Subscriptions'!A4:A103,SMALL(IF(MONTH('All Subscriptions'!F4:F103)=1,ROW('All Subscriptions'!F4:F103)-3),5)),"") | C10: =IFERROR(INDEX('All Subscriptions'!B4:B103,SMALL(IF(MONTH('All Subscriptions'!F4:F103)=1,ROW('All Subscriptions'!F4:F103)-3),5)),"") | D10: =IFERROR(INDEX('All Subscriptions'!F4:F103,SMALL(IF(MONTH('All Subscriptions'!F4:F103)=1,ROW('All Subscriptions'!F4:F103)-3),5)),"") | E10: =IFERROR(INDEX('All Subscriptions'!C4:C103,SMALL(IF(MONTH('All Subscriptions'!F4:F103)=1,ROW('All Subscriptions'!F4:F103)-3),5)),"")
B11: =IFERROR(INDEX('All Subscriptions'!A4:A103,SMALL(IF(MONTH('All Subscriptions'!F4:F103)=1,ROW('All Subscriptions'!F4:F103)-3),6)),"") | C11: =IFERROR(INDEX('All Subscriptions'!B4:B103,SMALL(IF(MONTH('All Subscriptions'!F4:F103)=1,ROW('All Subscriptions'!F4:F103)-3),6)),"") | D11: =IFERROR(INDEX('All Subscriptions'!F4:F103,SMALL(IF(MONTH('All Subscriptions'!F4:F103)=1,ROW('All Subscriptions'!F4:F103)-3),6)),"") | E11: =IFERROR(INDEX('All Subscriptions'!C4:C103,SMALL(IF(MONTH('All Subscriptions'!F4:F103)=1,ROW('All Subscriptions'!F4:F103)-3),6)),"")
B12: =IFERROR(INDEX('All Subscriptions'!A4:A103,SMALL(IF(MONTH('All Subscriptions'!F4:F103)=1,ROW('All Subscriptions'!F4:F103)-3),7)),"") | C12: =IFERROR(INDEX('All Subscriptions'!B4:B103,SMALL(IF(MONTH('All Subscriptions'!F4:F103)=1,ROW('All Subscriptions'!F4:F103)-3),7)),"") | D12: =IFERROR(INDEX('All Subscriptions'!F4:F103,SMALL(IF(MONTH('All Subscriptions'!F4:F103)=1,ROW('All Subscriptions'!F4:F103)-3),7)),"") | E12: =IFERROR(INDEX('All Subscriptions'!C4:C103,SMALL(IF(MONTH('All Subscriptions'!F4:F103)=1,ROW('All Subscriptions'!F4:F103)-3),7)),"")
B13: =IFERROR(INDEX('All Subscriptions'!A4:A103,SMALL(IF(MONTH('All Subscriptions'!F4:F103)=1,ROW('All Subscriptions'!F4:F103)-3),8)),"") | C13: =IFERROR(INDEX('All Subscriptions'!B4:B103,SMALL(IF(MONTH('All Subscriptions'!F4:F103)=1,ROW('All Subscriptions'!F4:F103)-3),8)),"") | D13: =IFERROR(INDEX('All Subscriptions'!F4:F103,SMALL(IF(MONTH('All Subscriptions'!F4:F103)=1,ROW('All Subscriptions'!F4:F103)-3),8)),"") | E13: =IFERROR(INDEX('All Subscriptions'!C4:C103,SMALL(IF(MONTH('All Subscriptions'!F4:F103)=1,ROW('All Subscriptions'!F4:F103)-3),8)),"")
B14: =IFERROR(INDEX('All Subscriptions'!A4:A103,SMALL(IF(MONTH('All Subscriptions'!F4:F103)=1,ROW('All Subscriptions'!F4:F103)-3),9)),"") | C14: =IFERROR(INDEX('All Subscriptions'!B4:B103,SMALL(IF(MONTH('All Subscriptions'!F4:F103)=1,ROW('All Subscriptions'!F4:F103)-3),9)),"") | D14: =IFERROR(INDEX('All Subscriptions'!F4:F103,SMALL(IF(MONTH('All Subscriptions'!F4:F103)=1,ROW('All Subscriptions'!F4:F103)-3),9)),"") | E14: =IFERROR(INDEX('All Subscriptions'!C4:C103,SMALL(IF(MONTH('All Subscriptions'!F4:F103)=1,ROW('All Subscriptions'!F4:F103)-3),9)),"")
B15: =IFERROR(INDEX('All Subscriptions'!A4:A103,SMALL(IF(MONTH('All Subscriptions'!F4:F103)=1,ROW('All Subscriptions'!F4:F103)-3),10)),"") | C15: =IFERROR(INDEX('All Subscriptions'!B4:B103,SMALL(IF(MONTH('All Subscriptions'!F4:F103)=1,ROW('All Subscriptions'!F4:F103)-3),10)),"") | D15: =IFERROR(INDEX('All Subscriptions'!F4:F103,SMALL(IF(MONTH('All Subscriptions'!F4:F103)=1,ROW('All Subscriptions'!F4:F103)-3),10)),"") | E15: =IFERROR(INDEX('All Subscriptions'!C4:C103,SMALL(IF(MONTH('All Subscriptions'!F4:F103)=1,ROW('All Subscriptions'!F4:F103)-3),10)),"")
B16: =IFERROR(INDEX('All Subscriptions'!A4:A103,SMALL(IF(MONTH('All Subscriptions'!F4:F103)=1,ROW('All Subscriptions'!F4:F103)-3),11)),"") | C16: =IFERROR(INDEX('All Subscriptions'!B4:B103,SMALL(IF(MONTH('All Subscriptions'!F4:F103)=1,ROW('All Subscriptions'!F4:F103)-3),11)),"") | D16: =IFERROR(INDEX('All Subscriptions'!F4:F103,SMALL(IF(MONTH('All Subscriptions'!F4:F103)=1,ROW('All Subscriptions'!F4:F103)-3),11)),"") | E16: =IFERROR(INDEX('All Subscriptions'!C4:C103,SMALL(IF(MONTH('All Subscriptions'!F4:F103)=1,ROW('All Subscriptions'!F4:F103)-3),11)),"")
B17: =IFERROR(INDEX('All Subscriptions'!A4:A103,SMALL(IF(MONTH('All Subscriptions'!F4:F103)=1,ROW('All Subscriptions'!F4:F103)-3),12)),"") | C17: =IFERROR(INDEX('All Subscriptions'!B4:B103,SMALL(IF(MONTH('All Subscriptions'!F4:F103)=1,ROW('All Subscriptions'!F4:F103)-3),12)),"") | D17: =IFERROR(INDEX('All Subscriptions'!F4:F103,SMALL(IF(MONTH('All Subscriptions'!F4:F103)=1,ROW('All Subscriptions'!F4:F103)-3),12)),"") | E17: =IFERROR(INDEX('All Subscriptions'!C4:C103,SMALL(IF(MONTH('All Subscriptions'!F4:F103)=1,ROW('All Subscriptions'!F4:F103)-3),12)),"")
B18: January Total | E18: =SUMPRODUCT((MONTH('All Subscriptions'!F4:F103)=1)*('All Subscriptions'!I4:I103<>"Canceled")*'All Subscriptions'!C4:C103)
B20: FEBRUARY
B21: Service | C21: Category | D21: Renewal Date | E21: Amount
B22: =IFERROR(INDEX('All Subscriptions'!A4:A103,SMALL(IF(MONTH('All Subscriptions'!F4:F103)=2,ROW('All Subscriptions'!F4:F103)-3),1)),"") | C22: =IFERROR(INDEX('All Subscriptions'!B4:B103,SMALL(IF(MONTH('All Subscriptions'!F4:F103)=2,ROW('All Subscriptions'!F4:F103)-3),1)),"") | D22: =IFERROR(INDEX('All Subscriptions'!F4:F103,SMALL(IF(MONTH('All Subscriptions'!F4:F103)=2,ROW('All Subscriptions'!F4:F103)-3),1)),"") | E22: =IFERROR(INDEX('All Subscriptions'!C4:C103,SMALL(IF(MONTH('All Subscriptions'!F4:F103)=2,ROW('All Subscriptions'!F4:F103)-3),1)),"")
B23: =IFERROR(INDEX('All Subscriptions'!A4:A103,SMALL(IF(MONTH('All Subscriptions'!F4:F103)=2,ROW('All Subscriptions'!F4:F103)-3),2)),"") | C23: =IFERROR(INDEX('All Subscriptions'!B4:B103,SMALL(IF(MONTH('All Subscriptions'!F4:F103)=2,ROW('All Subscriptions'!F4:F103)-3),2)),"") | D23: =IFERROR(INDEX('All Subscriptions'!F4:F103,SMALL(IF(MONTH('All Subscriptions'!F4:F103)=2,ROW('All Subscriptions'!F4:F103)-3),2)),"") | E23: =IFERROR(INDEX('All Subscriptions'!C4:C103,SMALL(IF(MONTH('All Subscriptions'!F4:F103)=2,ROW('All Subscriptions'!F4:F103)-3),2)),"")
B24: =IFERROR(INDEX('All Subscriptions'!A4:A103,SMALL(IF(MONTH('All Subscriptions'!F4:F103)=2,ROW('All Subscriptions'!F4:F103)-3),3)),"") | C24: =IFERROR(INDEX('All Subscriptions'!B4:B103,SMALL(IF(MONTH('All Subscriptions'!F4:F103)=2,ROW('All Subscriptions'!F4:F103)-3),3)),"") | D24: =IFERROR(INDEX('All Subscriptions'!F4:F103,SMALL(IF(MONTH('All Subscriptions'!F4:F103)=2,ROW('All Subscriptions'!F4:F103)-3),3)),"") | E24: =IFERROR(INDEX('All Subscriptions'!C4:C103,SMALL(IF(MONTH('All Subscriptions'!F4:F103)=2,ROW('All Subscriptions'!F4:F103)-3),3)),"")
B25: =IFERROR(INDEX('All Subscriptions'!A4:A103,SMALL(IF(MONTH('All Subscriptions'!F4:F103)=2,ROW('All Subscriptions'!F4:F103)-3),4)),"") | C25: =IFERROR(INDEX('All Subscriptions'!B4:B103,SMALL(IF(MONTH('All Subscriptions'!F4:F103)=2,ROW('All Subscriptions'!F4:F103)-3),4)),"") | D25: =IFERROR(INDEX('All Subscriptions'!F4:F103,SMALL(IF(MONTH('All Subscriptions'!F4:F103)=2,ROW('All Subscriptions'!F4:F103)-3),4)),"") | E25: =IFERROR(INDEX('All Subscriptions'!C4:C103,SMALL(IF(MONTH('All Subscriptions'!F4:F103)=2,ROW('All Subscriptions'!F4:F103)-3),4)),"")
B26: =IFERROR(INDEX('All Subscriptions'!A4:A103,SMALL(IF(MONTH('All Subscriptions'!F4:F103)=2,ROW('All Subscriptions'!F4:F103)-3),5)),"") | C26: =IFERROR(INDEX('All Subscriptions'!B4:B103,SMALL(IF(MONTH('All Subscriptions'!F4:F103)=2,ROW('All Subscriptions'!F4:F103)-3),5)),"") | D26: =IFERROR(INDEX('All Subscriptions'!F4:F103,SMALL(IF(MONTH('All Subscriptions'!F4:F103)=2,ROW('All Subscriptions'!F4:F103)-3),5)),"") | E26: =IFERROR(INDEX('All Subscriptions'!C4:C103,SMALL(IF(MONTH('All Subscriptions'!F4:F103)=2,ROW('All Subscriptions'!F4:F103)-3),5)),"")
B27: =IFERROR(INDEX('All Subscriptions'!A4:A103,SMALL(IF(MONTH('All Subscriptions'!F4:F103)=2,ROW('All Subscriptions'!F4:F103)-3),6)),"") | C27: =IFERROR(INDEX('All Subscriptions'!B4:B103,SMALL(IF(MONTH('All Subscriptions'!F4:F103)=2,ROW('All Subscriptions'!F4:F103)-3),6)),"") | D27: =IFERROR(INDEX('All Subscriptions'!F4:F103,SMALL(IF(MONTH('All Subscriptions'!F4:F103)=2,ROW('All Subscriptions'!F4:F103)-3),6)),"") | E27: =IFERROR(INDEX('All Subscriptions'!C4:C103,SMALL(IF(MONTH('All Subscriptions'!F4:F103)=2,ROW('All Subscriptions'!F4:F103)-3),6)),"")
B28: =IFERROR(INDEX('All Subscriptions'!A4:A103,SMALL(IF(MONTH('All Subscriptions'!F4:F103)=2,ROW('All Subscriptions'!F4:F103)-3),7)),"") | C28: =IFERROR(INDEX('All Subscriptions'!B4:B103,SMALL(IF(MONTH('All Subscriptions'!F4:F103)=2,ROW('All Subscriptions'!F4:F103)-3),7)),"") | D28: =IFERROR(INDEX('All Subscriptions'!F4:F103,SMALL(IF(MONTH('All Subscriptions'!F4:F103)=2,ROW('All Subscriptions'!F4:F103)-3),7)),"") | E28: =IFERROR(INDEX('All Subscriptions'!C4:C103,SMALL(IF(MONTH('All Subscriptions'!F4:F103)=2,ROW('All Subscriptions'!F4:F103)-3),7)),"")
B29: =IFERROR(INDEX('All Subscriptions'!A4:A103,SMALL(IF(MONTH('All Subscriptions'!F4:F103)=2,ROW('All Subscriptions'!F4:F103)-3),8)),"") | C29: =IFERROR(INDEX('All Subscriptions'!B4:B103,SMALL(IF(MONTH('All Subscriptions'!F4:F103)=2,ROW('All Subscriptions'!F4:F103)-3),8)),"") | D29: =IFERROR(INDEX('All Subscriptions'!F4:F103,SMALL(IF(MONTH('All Subscriptions'!F4:F103)=2,ROW('All Subscriptions'!F4:F103)-3),8)),"") | E29: =IFERROR(INDEX('All Subscriptions'!C4:C103,SMALL(IF(MONTH('All Subscriptions'!F4:F103)=2,ROW('All Subscriptions'!F4:F103)-3),8)),"")
B30: =IFERROR(INDEX('All Subscriptions'!A4:A103,SMALL(IF(MONTH('All Subscriptions'!F4:F103)=2,ROW('All Subscriptions'!F4:F103)-3),9)),"") | C30: =IFERROR(INDEX('All Subscriptions'!B4:B103,SMALL(IF(MONTH('All Subscriptions'!F4:F103)=2,ROW('All Subscriptions'!F4:F103)-3),9)),"") | D30: =IFERROR(INDEX('All Subscriptions'!F4:F103,SMALL(IF(MONTH('All Subscriptions'!F4:F103)=2,ROW('All Subscriptions'!F4:F103)-3),9)),"") | E30: =IFERROR(INDEX('All Subscriptions'!C4:C103,SMALL(IF(MONTH('All Subscriptions'!F4:F103)=2,ROW('All Subscriptions'!F4:F103)-3),9)),"")
B31: =IFERROR(INDEX('All Subscriptions'!A4:A103,SMALL(IF(MONTH('All Subscriptions'!F4:F103)=2,ROW('All Subscriptions'!F4:F103)-3),10)),"") | C31: =IFERROR(INDEX('All Subscriptions'!B4:B103,SMALL(IF(MONTH('All Subscriptions'!F4:F103)=2,ROW('All Subscriptions'!F4:F103)-3),10)),"") | D31: =IFERROR(INDEX('All Subscriptions'!F4:F103,SMALL(IF(MONTH('All Subscriptions'!F4:F103)=2,ROW('All Subscriptions'!F4:F103)-3),10)),"") | E31: =IFERROR(INDEX('All Subscriptions'!C4:C103,SMALL(IF(MONTH('All Subscriptions'!F4:F103)=2,ROW('All Subscriptions'!F4:F103)-3),10)),"")
B32: =IFERROR(INDEX('All Subscriptions'!A4:A103,SMALL(IF(MONTH('All Subscriptions'!F4:F103)=2,ROW('All Subscriptions'!F4:F103)-3),11)),"") | C32: =IFERROR(INDEX('All Subscriptions'!B4:B103,SMALL(IF(MONTH('All Subscriptions'!F4:F103)=2,ROW('All Subscriptions'!F4:F103)-3),11)),"") | D32: =IFERROR(INDEX('All Subscriptions'!F4:F103,SMALL(IF(MONTH('All Subscriptions'!F4:F103)=2,ROW('All Subscriptions'!F4:F103)-3),11)),"") | E32: =IFERROR(INDEX('All Subscriptions'!C4:C103,SMALL(IF(MONTH('All Subscriptions'!F4:F103)=2,ROW('All Subscriptions'!F4:F103)-3),11)),"")
B33: =IFERROR(INDEX('All Subscriptions'!A4:A103,SMALL(IF(MONTH('All Subscriptions'!F4:F103)=2,ROW('All Subscriptions'!F4:F103)-3),12)),"") | C33: =IFERROR(INDEX('All Subscriptions'!B4:B103,SMALL(IF(MONTH('All Subscriptions'!F4:F103)=2,ROW('All Subscriptions'!F4:F103)-3),12)),"") | D33: =IFERROR(INDEX('All Subscriptions'!F4:F103,SMALL(IF(MONTH('All Subscriptions'!F4:F103)=2,ROW('All Subscriptions'!F4:F103)-3),12)),"") | E33: =IFERROR(INDEX('All Subscriptions'!C4:C103,SMALL(IF(MONTH('All Subscriptions'!F4:F103)=2,ROW('All Subscriptions'!F4:F103)-3),12)),"")
B34: February Total | E34: =SUMPRODUCT((MONTH('All Subscriptions'!F4:F103)=2)*('All Subscriptions'!I4:I103<>"Canceled")*'All Subscriptions'!C4:C103)
B36: MARCH
B37: Service | C37: Category | D37: Renewal Date | E37: Amount
B38: =IFERROR(INDEX('All Subscriptions'!A4:A103,SMALL(IF(MONTH('All Subscriptions'!F4:F103)=3,ROW('All Subscriptions'!F4:F103)-3),1)),"") | C38: =IFERROR(INDEX('All Subscriptions'!B4:B103,SMALL(IF(MONTH('All Subscriptions'!F4:F103)=3,ROW('All Subscriptions'!F4:F103)-3),1)),"") | D38: =IFERROR(INDEX('All Subscriptions'!F4:F103,SMALL(IF(MONTH('All Subscriptions'!F4:F103)=3,ROW('All Subscriptions'!F4:F103)-3),1)),"") | E38: =IFERROR(INDEX('All Subscriptions'!C4:C103,SMALL(IF(MONTH('All Subscriptions'!F4:F103)=3,ROW('All Subscriptions'!F4:F103)-3),1)),"")
B39: =IFERROR(INDEX('All Subscriptions'!A4:A103,SMALL(IF(MONTH('All Subscriptions'!F4:F103)=3,ROW('All Subscriptions'!F4:F103)-3),2)),"") | C39: =IFERROR(INDEX('All Subscriptions'!B4:B103,SMALL(IF(MONTH('All Subscriptions'!F4:F103)=3,ROW('All Subscriptions'!F4:F103)-3),2)),"") | D39: =IFERROR(INDEX('All Subscriptions'!F4:F103,SMALL(IF(MONTH('All Subscriptions'!F4:F103)=3,ROW('All Subscriptions'!F4:F103)-3),2)),"") | E39: =IFERROR(INDEX('All Subscriptions'!C4:C103,SMALL(IF(MONTH('All Subscriptions'!F4:F103)=3,ROW('All Subscriptions'!F4:F103)-3),2)),"")
B40: =IFERROR(INDEX('All Subscriptions'!A4:A103,SMALL(IF(MONTH('All Subscriptions'!F4:F103)=3,ROW('All Subscriptions'!F4:F103)-3),3)),"") | C40: =IFERROR(INDEX('All Subscriptions'!B4:B103,SMALL(IF(MONTH('All Subscriptions'!F4:F103)=3,ROW('All Subscriptions'!F4:F103)-3),3)),"") | D40: =IFERROR(INDEX('All Subscriptions'!F4:F103,SMALL(IF(MONTH('All Subscriptions'!F4:F103)=3,ROW('All Subscriptions'!F4:F103)-3),3)),"") | E40: =IFERROR(INDEX('All Subscriptions'!C4:C103,SMALL(IF(MONTH('All Subscriptions'!F4:F103)=3,ROW('All Subscriptions'!F4:F103)-3),3)),"")
B41: =IFERROR(INDEX('All Subscriptions'!A4:A103,SMALL(IF(MONTH('All Subscriptions'!F4:F103)=3,ROW('All Subscriptions'!F4:F103)-3),4)),"") | C41: =IFERROR(INDEX('All Subscriptions'!B4:B103,SMALL(IF(MONTH('All Subscriptions'!F4:F103)=3,ROW('All Subscriptions'!F4:F103)-3),4)),"") | D41: =IFERROR(INDEX('All Subscriptions'!F4:F103,SMALL(IF(MONTH('All Subscriptions'!F4:F103)=3,ROW('All Subscriptions'!F4:F103)-3),4)),"") | E41: =IFERROR(INDEX('All Subscriptions'!C4:C103,SMALL(IF(MONTH('All Subscriptions'!F4:F103)=3,ROW('All Subscriptions'!F4:F103)-3),4)),"")
B42: =IFERROR(INDEX('All Subscriptions'!A4:A103,SMALL(IF(MONTH('All Subscriptions'!F4:F103)=3,ROW('All Subscriptions'!F4:F103)-3),5)),"") | C42: =IFERROR(INDEX('All Subscriptions'!B4:B103,SMALL(IF(MONTH('All Subscriptions'!F4:F103)=3,ROW('All Subscriptions'!F4:F103)-3),5)),"") | D42: =IFERROR(INDEX('All Subscriptions'!F4:F103,SMALL(IF(MONTH('All Subscriptions'!F4:F103)=3,ROW('All Subscriptions'!F4:F103)-3),5)),"") | E42: =IFERROR(INDEX('All Subscriptions'!C4:C103,SMALL(IF(MONTH('All Subscriptions'!F4:F103)=3,ROW('All Subscriptions'!F4:F103)-3),5)),"")
B43: =IFERROR(INDEX('All Subscriptions'!A4:A103,SMALL(IF(MONTH('All Subscriptions'!F4:F103)=3,ROW('All Subscriptions'!F4:F103)-3),6)),"") | C43: =IFERROR(INDEX('All Subscriptions'!B4:B103,SMALL(IF(MONTH('All Subscriptions'!F4:F103)=3,ROW('All Subscriptions'!F4:F103)-3),6)),"") | D43: =IFERROR(INDEX('All Subscriptions'!F4:F103,SMALL(IF(MONTH('All Subscriptions'!F4:F103)=3,ROW('All Subscriptions'!F4:F103)-3),6)),"") | E43: =IFERROR(INDEX('All Subscriptions'!C4:C103,SMALL(IF(MONTH('All Subscriptions'!F4:F103)=3,ROW('All Subscriptions'!F4:F103)-3),6)),"")
...

Sheet Annual Summary
A1: ANNUAL SUMMARY
A2: Track your subscription spending month by month. Enter actual monthly totals below.
B4: MONTH-BY-MONTH SPENDING
C5: Jan | D5: Feb | E5: Mar | F5: Apr | G5: May | H5: Jun | I5: Jul | J5: Aug | K5: Sep | L5: Oct | M5: Nov | N5: Dec | O5: TOTAL
B6: Current Year | O6: =SUM(C6:N6)
B7: Previous Year | O7: =SUM(C7:N7)
B8: Difference (+/-) | C8: =C6-C7 | D8: =D6-D7 | E8: =E6-E7 | F8: =F6-F7 | G8: =G6-G7 | H8: =H6-H7 | I8: =I6-I7 | J8: =J6-J7 | ... O8: =O6-O7
B10: CATEGORY-BY-CATEGORY ANNUAL BREAKDOWN
C11: Jan | D11: Feb | E11: Mar | F11: Apr | G11: May | H11: Jun | I11: Jul | J11: Aug | K11: Sep | L11: Oct | M11: Nov | N11: Dec | O11: TOTAL
B12: Entertainment | O12: =SUM(C12:N12)
B13: Software | O13: =SUM(C13:N13)
B14: Health & Fitness | O14: =SUM(C14:N14)
B15: News & Media | O15: =SUM(C15:N15)
B16: Food & Delivery | O16: =SUM(C16:N16)
B17: Cloud Storage | O17: =SUM(C17:N17)
B18: Music | O18: =SUM(C18:N18)
B19: Gaming | O19: =SUM(C19:N19)
B20: Productivity | O20: =SUM(C20:N20)
B21: Other | O21: =SUM(C21:N21)
B22: TOTAL | C22: =SUM(C12:C21) | D22: =SUM(D12:D21) | E22: =SUM(E12:E21) | F22: =SUM(F12:F21) | G22: =SUM(G12:G21) | H22: =SUM(H12:H21) | I22: =SUM(I12:I21) | J22: =SUM(J12:J21) | ... O22: =SUM(O12:O21)
B24: TOTAL SAVED FROM CANCELLATIONS
B25: Monthly Savings (from log) | C25: =SUM('Cancellation Log'!C5:C104)
B26: Annual Savings (from log) | C26: =SUM('Cancellation Log'!D5:D104)

Sheet Cancellation Log
A1: CANCELLATION LOG
A2: Every subscription you cancel puts money back in your pocket. Track your wins below!
A3: YOU'VE SAVED THIS YEAR: | C3: =SUM(C5:C104) | D3: =SUM(D5:D104)
A4: Service Name | B4: Date Canceled | C4: Monthly Savings | D4: Annual Savings | E4: Reason | F4: Would Re-subscribe?
D5: =IF(C5="",0,C5*12)
D6: =IF(C6="",0,C6*12)
D7: =IF(C7="",0,C7*12)
D8: =IF(C8="",0,C8*12)
D9: =IF(C9="",0,C9*12)
D10: =IF(C10="",0,C10*12)
D11: =IF(C11="",0,C11*12)
D12: =IF(C12="",0,C12*12)
D13: =IF(C13="",0,C13*12)
D14: =IF(C14="",0,C14*12)
D15: =IF(C15="",0,C15*12)
D16: =IF(C16="",0,C16*12)
... D104: =IF(C104="",0,C104*12)
